Workbook

Sheet Count Sheet
A1: Number | B1: Description | C1: Magazijn | D1: Winkel | E1: Total
A3: 0101 | B3: VD DRAAD 1.5 mm ZWART | C3: __________ | D3: __________ | E3: ___________
A4: 0102 | B4: VD DRAAD 2.5 mm BRUIN | C4: __________ | D4: __________ | E4: ___________
A5: 0103 | B5: VD DRAAD 2.5 mm BLAUW | C5: __________ | D5: __________ | E5: ___________
A6: 0104 | B6: VD DRAAD 2.5 mm GR/GL | C6: __________ | D6: __________ | E6: ___________
A7: 0106 | B7: VD DRAAD 2.5 mm GR/GL | C7: __________ | D7: __________ | E7: ___________
A8: 0107 | B8: VD DRAAD 4 mm GL/GR | C8: __________ | D8: __________ | E8: ___________
A9: 0108 | B9: VD DRAAD 6 mm ZWART | C9: __________ | D9: __________ | E9: ___________
A10: 0109 | B10: VD DRAAD 6 mm BLAUW | C10: __________ | D10: __________ | E10: ___________
A11: 0110 | B11: VD DRAAD 6 mm GR/GL | C11: __________ | D11: __________ | E11: ___________
A12: 0111 | B12: VD DRAAD 10 mm ZWART | C12: __________ | D12: __________ | E12: ___________
A13: 0112 | B13: VD DRAAD 10 mm BLAUW | C13: __________ | D13: __________ | E13: ___________
... A2218: 9725 | B2218: REST YMVKAS 4X95MM | C2218: __________ | D2218: __________ | E2218: ___________

Sheet PILOTO
B1: Deposito Nro
I2: Cajas import | J2: Total | K2: Observaciones
B3: Fecha | C3: Código | D3: Referencia | E3: Cajas | F3: Sueltos | G3: Cajas 0x0 | H3: Sueltos | J3: Unidades

Sheet Catalog
A1: code_item | B1: description_item | C1: current_inventory
A2: 0101 | B2: VD DRAAD 1.5 mm ZWART | C2: 0
A3: 0102 | B3: VD DRAAD 2.5 mm BRUIN | C3: 0
A4: 0103 | B4: VD DRAAD 2.5 mm BLAUW | C4: 0
A5: 0104 | B5: VD DRAAD 2.5 mm GR/GL | C5: 0
A6: 0106 | B6: VD DRAAD 2.5 mm GR/GL | C6: 0
A7: 0107 | B7: VD DRAAD 4 mm GL/GR | C7: 0
A8: 0108 | B8: VD DRAAD 6 mm ZWART | C8: 0
A9: 0109 | B9: VD DRAAD 6 mm BLAUW | C9: 0
A10: 0110 | B10: VD DRAAD 6 mm GR/GL | C10: 0
A11: 0111 | B11: VD DRAAD 10 mm ZWART | C11: 0
A12: 0112 | B12: VD DRAAD 10 mm BLAUW | C12: 0
A13: 0113 | B13: VD DRAAD 10 mm GR/GL | C13: 0
... A488: 0999 | B488: WCD AM INB D 220V R/A 815W | C488: 0
A489: 1000 | B489: SCHAK AM WIS DUB 276W | C489: 0
A490: 1001 | B490: 5 BTTN TIMER 127V PT18M-W | C490: 0
A491: 1002 | B491: SCHAK AM ENK POL 271W | C491: 0
A492: 1003 | B492: SCHAK AM 2POL CS215W | C492: 0
A493: 1004 | B493: SCHAK AM ENK INB 1301W | C493: 0
A494: 1005 | B494: SCHAK AM WIS INB 1303W | C494: 0
A495: 1006 | B495: SCHAK AM ENK DECO 7501W | C495: 0
A496: 1007 | B496: SCHAK AM WIS DECO 7503W | C496: 0
A497: 1008 | B497: SCHAK AM DUB DECO 7728W | C497: 0
A498: 1009 | B498: SCHAK AM TRI DECO 7729W | C498: 0
A499: 10090 | B499: SCHAK DUB WISSEL DECO 7731W | C499: 0
A500: 10091 | B500: SCHAK AM 2P DEC 20A 7622W | C500: 0
... A2217: 9725 | B2217: REST YMVKAS 4X95MM | C2217: 0

Sheet D1 (V)
B1: Deposito Nro 1
B2: B-4 | I2: Cajas import | J2: Total | K2: Observaciones
B3: Fecha | C3: Código | D3: Referencia | E3: Cajas | F3: Sueltos | G3: Cajas 0x0 | H3: Sueltos | J3: Unidades
B4: 26-01-2026 | C4: 4040 | D4: {=IFERROR(_xlfn.XLOOKUP(TEXT(C4,"0000"),TEXT(Catalog!A:A,"0000"),Catalog!B:B),"")} -> SINGLE POLE SWITCH 37011 OPB | E4: 2X100 | F4: 1
B5: 26-01-2026 | C5: 4042 | D5: {=IFERROR(_xlfn.XLOOKUP(TEXT(C5,"0000"),TEXT(Catalog!A:A,"0000"),Catalog!B:B),"")} -> TWO-WAY SWITCH 37071 OPB | E5: 24
B6: 26-01-2026 | C6: 4041 | D6: {=IFERROR(_xlfn.XLOOKUP(TEXT(C6,"0000"),TEXT(Catalog!A:A,"0000"),Catalog!B:B),"")} -> TWO CIRCUITS SWITCH 37061 OPB | E6: 31
B7: 26-01-2026 | C7: 4043 | D7: {=IFERROR(_xlfn.XLOOKUP(TEXT(C7,"0000"),TEXT(Catalog!A:A,"0000"),Catalog!B:B),"")} -> DOUBLE 2-WAY SWITCH 37101 OPB | E7: 15
B8: 26-01-2026 | C8: 4050 | D8: {=IFERROR(_xlfn.XLOOKUP(TEXT(C8,"0000"),TEXT(Catalog!A:A,"0000"),Catalog!B:B),"")} -> EARTH SOCKET 48131 OPB WD | E8: 3
B9: 26-01-2026 | C9: 4046 | D9: {=IFERROR(_xlfn.XLOOKUP(TEXT(C9,"0000"),TEXT(Catalog!A:A,"0000"),Catalog!B:B),"")} -> SINGLE POLE SWITCH 48011 OP WD | E9: 11
B10: 26-01-2026 | C10: 4049 | D10: {=IFERROR(_xlfn.XLOOKUP(TEXT(C10,"0000"),TEXT(Catalog!A:A,"0000"),Catalog!B:B),"")} -> TWO WAY SWITCH 48071 OPB WD | E10: 7
B11: 26-01-2026 | C11: 4047 | D11: {=IFERROR(_xlfn.XLOOKUP(TEXT(C11,"0000"),TEXT(Catalog!A:A,"0000"),Catalog!B:B),"")} -> TWO POLE SWITCH 48021 WD OPB | E11: 7
B12: 26-01-2026 | C12: 4048 | D12: {=IFERROR(_xlfn.XLOOKUP(TEXT(C12,"0000"),TEXT(Catalog!A:A,"0000"),Catalog!B:B),"")} -> 2 CIRCUITS SWITCH 48061 OPB WD | E12: 9
B13: 26-01-2026 | C13: 4024 | D13: {=IFERROR(_xlfn.XLOOKUP(TEXT(C13,"0000"),TEXT(Catalog!A:A,"0000"),Catalog!B:B),"")} -> COV PL SCHUK SOCKET IP44 70634 | E13: 12
B14: 26-01-2026 | C14: 4035 | D14: {=IFERROR(_xlfn.XLOOKUP(TEXT(C14,"0000"),TEXT(Catalog!A:A,"0000"),Catalog!B:B),"")} -> WATERPROOF FRAME IP 44 70961 | E14: 4
B16: C-3 | I16: Cajas import | J16: Total | K16: Observaciones
B17: Fecha | C17: Código | D17: Referencia | E17: Cajas | F17: Sueltos | G17: Cajas 0x0 | H17: Sueltos | J17: Unidades
B18: 26-01-2026 | C18: 4106 | D18: {=IFERROR(_xlfn.XLOOKUP(TEXT(C18,"0000"),TEXT(Catalog!A:A,"0000"),Catalog!B:B),"")} -> COVER PLATE - TELEPHONE 90712
B19: 26-01-2026 | C19: 4145 | D19: {=IFERROR(_xlfn.XLOOKUP(TEXT(C19,"0000"),TEXT(Catalog!A:A,"0000"),Catalog!B:B),"")} -> COV PLATE TELEPHONE 90712 TPM | E19: 10
B20: 26-01-2026 | C20: 4105 | D20: {=IFERROR(_xlfn.XLOOKUP(TEXT(C20,"0000"),TEXT(Catalog!A:A,"0000"),Catalog!B:B),"")} -> COVER PLATE SINGLE RJ45 90751
B21: 26-01-2026 | C21: 4144 | D21: {=IFERROR(_xlfn.XLOOKUP(TEXT(C21,"0000"),TEXT(Catalog!A:A,"0000"),Catalog!B:B),"")} -> COV PLATE SINGLE RJ45 90751TPM
B22: 26-01-2026 | C22: 90106 | D22: {=IFERROR(_xlfn.XLOOKUP(TEXT(C22,"0000"),TEXT(Catalog!A:A,"0000"),Catalog!B:B),"")} -> COV PLATE SINGL RJ45 90751TAL | E22: 4
B23: 26-01-2026 | C23: 4103 | D23: {=IFERROR(_xlfn.XLOOKUP(TEXT(C23,"0000"),TEXT(Catalog!A:A,"0000"),Catalog!B:B),"")} -> COVER PLATE PULL CORD 90741 | E23: 18
B24: 26-01-2026 | C24: 4112 | D24: {=IFERROR(_xlfn.XLOOKUP(TEXT(C24,"0000"),TEXT(Catalog!A:A,"0000"),Catalog!B:B),"")} -> DOUBLE HORIZONTAL FRAME 90920
B25: 26-01-2026 | C25: 4151 | D25: {=IFERROR(_xlfn.XLOOKUP(TEXT(C25,"0000"),TEXT(Catalog!A:A,"0000"),Catalog!B:B),"")} -> 2 X HORIZONTAL FRAME 90920 TPM
B26: 26-01-2026 | C26: 90101 | D26: {=IFERROR(_xlfn.XLOOKUP(TEXT(C26,"0000"),TEXT(Catalog!A:A,"0000"),Catalog!B:B),"")} -> DOUBLE FRAME ALU 90920TAA | E26: 41
B27: 26-01-2026 | C27: 4109 | D27: {=IFERROR(_xlfn.XLOOKUP(TEXT(C27,"0000"),TEXT(Catalog!A:A,"0000"),Catalog!B:B),"")} -> COVER PLATE SCHUKO SOCKET90634
B28: 26-01-2026 | C28: 4148 | D28: {=IFERROR(_xlfn.XLOOKUP(TEXT(C28,"0000"),TEXT(Catalog!A:A,"0000"),Catalog!B:B),"")} -> COV PLATE SOCKET IP44 90634TPM | E28: 2
B29: 26-01-2026 | C29: 4116 | D29: {=IFERROR(_xlfn.XLOOKUP(TEXT(C29,"0000"),TEXT(Catalog!A:A,"0000"),Catalog!B:B),"")} -> WATERPROOF FRAME IP 44 90961 | E29: 5
B30: 26-01-2026 | C30: 4119 | D30: {=IFERROR(_xlfn.XLOOKUP(TEXT(C30,"0000"),TEXT(Catalog!A:A,"0000"),Catalog!B:B),"")} -> SURFACE MOUNTINGBOX 10976 ABR | E30: 4
B31: 26-01-2026 | C31: 4118 | D31: {=IFERROR(_xlfn.XLOOKUP(TEXT(C31,"0000"),TEXT(Catalog!A:A,"0000"),Catalog!B:B),"")} -> COVER PLATE DBL USB CHA90673
B32: 26-01-2026 | C32: 4156 | D32: {=IFERROR(_xlfn.XLOOKUP(TEXT(C32,"0000"),TEXT(Catalog!A:A,"0000"),Catalog!B:B),"")} -> COV PLATE FOR USB 90673 TPM | E32: 24
B33: 26-01-2026 | C33: 8021 | D33: {=IFERROR(_xlfn.XLOOKUP(TEXT(C33,"0000"),TEXT(Catalog!A:A,"0000"),Catalog!B:B),"")} -> CMH100/TT/UVC/730/E40 SKU 7739 | E33: 3
B34: 26-01-2026 | C34: 15142 | D34: {=IFERROR(_xlfn.XLOOKUP(TEXT(C34,"0000"),TEXT(Catalog!A:A,"0000"),Catalog!B:B),"")} -> OPBOUW KAST WD CSG13PT/RR | E34: 6
B35: 26-01-2026 | C35: 3997 | D35: {=IFERROR(_xlfn.XLOOKUP(TEXT(C35,"0000"),TEXT(Catalog!A:A,"0000"),Catalog!B:B),"")} -> SPEED CONTROLLER 21219 | E35: 13
B37: C-4 | I37: Cajas import | J37: Total | K37: Observaciones
B38: Fecha | C38: Código | D38: Referencia | E38: Cajas | F38: Sueltos | G38: Cajas 0x0 | H38: Sueltos | J38: Unidades
B39: 26-01-2026 | C39: 4209 | D39: {=IFERROR(_xlfn.XLOOKUP(TEXT(C39,"0000"),TEXT(Catalog!A:A,"0000"),Catalog!B:B),"")} -> KABELGOOT 75X20MM 10140 CBR | E39: 6 | F39: 11
B40: 26-01-2026 | C40: 4212 | D40: {=IFERROR(_xlfn.XLOOKUP(TEXT(C40,"0000"),TEXT(Catalog!A:A,"0000"),Catalog!B:B),"")} -> KABELGOOT 90X50MM 10180 RBR | E40: 1
B41: 26-01-2026 | C41: 4213 | D41: {=IFERROR(_xlfn.XLOOKUP(TEXT(C41,"0000"),TEXT(Catalog!A:A,"0000"),Catalog!B:B),"")} -> KABELGOOT 180X50MM 10290 RBR | E41: 13
B42: 26-01-2026 | C42: 4260 | D42: {=IFERROR(_xlfn.XLOOKUP(TEXT(C42,"0000"),TEXT(Catalog!A:A,"0000"),Catalog!B:B),"")} -> VERLENG 110X50MM 10094 RBR | F42: 13
...

Sheet D2 (V)
B1: Deposito Nro 2
B2: A-1 | I2: Cajas import | J2: Total | K2: Observaciones
B3: Fecha | C3: Código | D3: Referencia | E3: Cajas | F3: Sueltos | G3: Cajas 0x0 | H3: Sueltos | J3: Unidades
B4: 27-01-26 | C4: 1611 | D4: {=IFERROR(_xlfn.XLOOKUP(TEXT(C4,"0000"),TEXT(Catalog!A:A,"0000"),Catalog!B:B),"")} -> OPB.KAST OLINTHOS 2RIJ 24 PE | E4: 22
B5: 27-01-26 | C5: 1612 | D5: {=IFERROR(_xlfn.XLOOKUP(TEXT(C5,"0000"),TEXT(Catalog!A:A,"0000"),Catalog!B:B),"")} -> OPB.KAST OLINTHOS 3RIJ 36 PE | E5: 2
B6: 27-01-26 | C6: 1506 | D6: {=IFERROR(_xlfn.XLOOKUP(TEXT(C6,"0000"),TEXT(Catalog!A:A,"0000"),Catalog!B:B),"")} -> OPBOUWKAST 2-RIJ 36PE 610285 | E6: 1 | K6: Producto sin codigo por antiguo, este codigo mas nuevo aprox.
B7: 27-01-26 | C7: 1511 | D7: {=IFERROR(_xlfn.XLOOKUP(TEXT(C7,"0000"),TEXT(Catalog!A:A,"0000"),Catalog!B:B),"")} -> INBOUWKAST 2-RIJ 28MOD 610373 | E7: 8
B8: 27-01-26 | C8: 7196 | D8: {=IFERROR(_xlfn.XLOOKUP(TEXT(C8,"0000"),TEXT(Catalog!A:A,"0000"),Catalog!B:B),"")} -> INB.KAST MP56 METALBOX NG | E8: 4
B9: 27-01-26 | C9: 7195 | D9: {=IFERROR(_xlfn.XLOOKUP(TEXT(C9,"0000"),TEXT(Catalog!A:A,"0000"),Catalog!B:B),"")} -> INB.KAST MP42 METALBOX NG | E9: 7
B10: 27-01-26 | C10: 7193 | D10: {=IFERROR(_xlfn.XLOOKUP(TEXT(C10,"0000"),TEXT(Catalog!A:A,"0000"),Catalog!B:B),"")} -> INB.KAST MP14 METALBOX NG | E10: 8
B13: A-2 | I13: Cajas import | J13: Total | K13: Observaciones
B14: Fecha | C14: Código | D14: Referencia | E14: Cajas | F14: Sueltos | G14: Cajas 0x0 | H14: Sueltos | J14: Unidades
B15: 27-01-26 | C15: 7144 | D15: {=IFERROR(_xlfn.XLOOKUP(TEXT(C15,"0000"),TEXT(Catalog!A:A,"0000"),Catalog!B:B),"")} -> OPB.KAST WD 6MD R1306BR1 | E15: 8
B16: 27-01-26 | C16: 7148 | D16: {=IFERROR(_xlfn.XLOOKUP(TEXT(C16,"0000"),TEXT(Catalog!A:A,"0000"),Catalog!B:B),"")} -> OPB.KAST WD 8MD 1308BR1 | E16: 6
B17: 27-01-26 | C17: 7168 | D17: {=IFERROR(_xlfn.XLOOKUP(TEXT(C17,"0000"),TEXT(Catalog!A:A,"0000"),Catalog!B:B),"")} -> OPB.KAST WD 36MD 1336PR1 | E17: 2
B18: 27-01-26 | C18: 7194 | D18: {=IFERROR(_xlfn.XLOOKUP(TEXT(C18,"0000"),TEXT(Catalog!A:A,"0000"),Catalog!B:B),"")} -> INB.KAST MP28 METALBOX NG | E18: 12
B21: A-3 | I21: Cajas import | J21: Total | K21: Observaciones
B22: Fecha | C22: Código | D22: Referencia | E22: Cajas | F22: Sueltos | G22: Cajas 0x0 | H22: Sueltos | J22: Unidades
B23: 27-01-26 | C23: 1507 | D23: {=IFERROR(_xlfn.XLOOKUP(TEXT(C23,"0000"),TEXT(Catalog!A:A,"0000"),Catalog!B:B),"")} -> OPBOUWKAST4-RIJ VA 424 T 48PE | E23: 2
B24: 27-01-26 | C24: 1665 | D24: {=IFERROR(_xlfn.XLOOKUP(TEXT(C24,"0000"),TEXT(Catalog!A:A,"0000"),Catalog!B:B),"")} -> MOELLER INB BF-U-5/120 | E24: 2
B25: 27-01-26 | C25: 7151 | D25: {=IFERROR(_xlfn.XLOOKUP(TEXT(C25,"0000"),TEXT(Catalog!A:A,"0000"),Catalog!B:B),"")} -> OPB.KAST 28MD 5281R1 | E25: 31
B26: 27-01-26 | C26: 1657 | D26: {=IFERROR(_xlfn.XLOOKUP(TEXT(C26,"0000"),TEXT(Catalog!A:A,"0000"),Catalog!B:B),"")} -> MOELLER OPB BF-0-5/120 | E26: 1
B27: 27-01-26 | D27: Cajas de sueltos | K27: Foto
B30: A-4 | I30: Cajas import | J30: Total | K30: Observaciones
B31: Fecha | C31: Código | D31: Referencia | E31: Cajas | F31: Sueltos | G31: Cajas 0x0 | H31: Sueltos | J31: Unidades
B32: 27-01-26 | C32: 1664 | D32: {=IFERROR(_xlfn.XLOOKUP(TEXT(C32,"0000"),TEXT(Catalog!A:A,"0000"),Catalog!B:B),"")} -> MOELLER INB BF-U-4/96 | E32: 7
B33: 27-01-26 | C33: 7147 | D33: {=IFERROR(_xlfn.XLOOKUP(TEXT(C33,"0000"),TEXT(Catalog!A:A,"0000"),Catalog!B:B),"")} -> OPB.KAST WD 48MD 1348R1 | E33: 6
B34: 27-01-26 | C34: 7184 | D34: {=IFERROR(_xlfn.XLOOKUP(TEXT(C34,"0000"),TEXT(Catalog!A:A,"0000"),Catalog!B:B),"")} -> INB.KAST MP14 METALBOX | E34: 2
B35: 27-01-26 | C35: 7193 | D35: {=IFERROR(_xlfn.XLOOKUP(TEXT(C35,"0000"),TEXT(Catalog!A:A,"0000"),Catalog!B:B),"")} -> INB.KAST MP14 METALBOX NG | E35: 22
B38: A-5 | I38: Cajas import | J38: Total | K38: Observaciones
B39: Fecha | C39: Código | D39: Referencia | E39: Cajas | F39: Sueltos | G39: Cajas 0x0 | H39: Sueltos | J39: Unidades
B40: 27-01-26 | C40: 1985 | D40: {=IFERROR(_xlfn.XLOOKUP(TEXT(C40,"0000"),TEXT(Catalog!A:A,"0000"),Catalog!B:B),"")} -> MESPATROON HOUDER 160 A-NH-00 | E40: 36
B41: 27-01-26 | C41: 1988 | D41: {=IFERROR(_xlfn.XLOOKUP(TEXT(C41,"0000"),TEXT(Catalog!A:A,"0000"),Catalog!B:B),"")} -> MESPATROON HOUDER 400 A-NH-2 | E41: 22
B42: 27-01-26 | C42: 1987 | D42: {=IFERROR(_xlfn.XLOOKUP(TEXT(C42,"0000"),TEXT(Catalog!A:A,"0000"),Catalog!B:B),"")} -> MESPATROON HOUDER 250 A-NH-1 | E42: 1
B43: 27-01-26 | C43: 1659 | D43: {=IFERROR(_xlfn.XLOOKUP(TEXT(C43,"0000"),TEXT(Catalog!A:A,"0000"),Catalog!B:B),"")} -> MOELLER OPB BF-0-3/72 | E43: 7
B46: A-6 | I46: Cajas import | J46: Total | K46: Observaciones
B47: Fecha | C47: Código | D47: Referencia | E47: Cajas | F47: Sueltos | G47: Cajas 0x0 | H47: Sueltos | J47: Unidades
B48: 27-01-26 | C48: 7191 | D48: {=IFERROR(_xlfn.XLOOKUP(TEXT(C48,"0000"),TEXT(Catalog!A:A,"0000"),Catalog!B:B),"")} -> EARTH TERMINAL GREEN | F48: 53
B49: 27-01-26 | C49: 1658 | D49: {=IFERROR(_xlfn.XLOOKUP(TEXT(C49,"0000"),TEXT(Catalog!A:A,"0000"),Catalog!B:B),"")} -> MOELLER OPB BF-0-6/144 | E49: 3
B50: 27-01-26 | C50: 1666 | D50: {=IFERROR(_xlfn.XLOOKUP(TEXT(C50,"0000"),TEXT(Catalog!A:A,"0000"),Catalog!B:B),"")} -> MOELLER INB BF-U-6/144 | E50: 5
...

Sheet D3 (V)
B1: Deposito Nro 3
B2: C2 | I2: Cajas import | J2: Total | K2: Observaciones
B3: Fecha | C3: Código | D3: Referencia | E3: Cajas | F3: Sueltos | G3: Cajas 0x0 | H3: Sueltos | J3: Unidades
B4: 30-01-2026 | C4: 15144 | D4: {=IFERROR(_xlfn.XLOOKUP(TEXT(C4,"0000"),TEXT(Catalog!A:A,"0000"),Catalog!B:B),"")} -> OPB.KAST WD 36MD CDN36PT/RR | E4: 21
B5: 30-01-2026 | C5: 15145 | D5: {=IFERROR(_xlfn.XLOOKUP(TEXT(C5,"0000"),TEXT(Catalog!A:A,"0000"),Catalog!B:B),"")} -> OPB.KAST WD 54MD CDP54 PT/RR | E5: 12
B6: 30-01-2026 | C6: 7052 | D6: {=IFERROR(_xlfn.XLOOKUP(TEXT(C6,"0000"),TEXT(Catalog!A:A,"0000"),Catalog!B:B),"")} -> JUNCTION BOX 125A 4*11 | E6: 2
B7: 30-01-2026 | C7: 7051 | D7: {=IFERROR(_xlfn.XLOOKUP(TEXT(C7,"0000"),TEXT(Catalog!A:A,"0000"),Catalog!B:B),"")} -> JUNCTION BOX 125A 4*7 | E7: 37
B9: C1 | I9: Cajas import | J9: Total | K9: Observaciones
B10: Fecha | C10: Código | D10: Referencia | E10: Cajas | F10: Sueltos | G10: Cajas 0x0 | H10: Sueltos | J10: Unidades
B11: 30-01-2026 | C11: 0615 | D11: {=IFERROR(_xlfn.XLOOKUP(TEXT(C11,"0000"),TEXT(Catalog!A:A,"0000"),Catalog!B:B),"")} -> ZEKERING 63A | E11: 1325
B12: 30-01-2026 | C12: 0614 | D12: {=IFERROR(_xlfn.XLOOKUP(TEXT(C12,"0000"),TEXT(Catalog!A:A,"0000"),Catalog!B:B),"")} -> ZEKERING 50A | E12: 950
B13: 30-01-2026 | C13: 0613 | D13: {=IFERROR(_xlfn.XLOOKUP(TEXT(C13,"0000"),TEXT(Catalog!A:A,"0000"),Catalog!B:B),"")} -> ZEKERING 35A | E13: 875
B14: 30-01-2026 | C14: 0612 | D14: {=IFERROR(_xlfn.XLOOKUP(TEXT(C14,"0000"),TEXT(Catalog!A:A,"0000"),Catalog!B:B),"")} -> ZEKERING 25A | E14: 477
B15: 30-01-2026 | C15: 0611 | D15: {=IFERROR(_xlfn.XLOOKUP(TEXT(C15,"0000"),TEXT(Catalog!A:A,"0000"),Catalog!B:B),"")} -> ZEKERING 20A | E15: 1300
B16: 30-01-2026 | C16: 0610 | D16: {=IFERROR(_xlfn.XLOOKUP(TEXT(C16,"0000"),TEXT(Catalog!A:A,"0000"),Catalog!B:B),"")} -> ZEKERING 16A | E16: 500
B18: C7 | I18: Cajas import | J18: Total | K18: Observaciones
B19: Fecha | C19: Código | D19: Referencia | E19: Cajas | F19: Sueltos | G19: Cajas 0x0 | H19: Sueltos | J19: Unidades
B20: 30-01-2026 | C20: 0577 | D20: {=IFERROR(_xlfn.XLOOKUP(TEXT(C20,"0000"),TEXT(Catalog!A:A,"0000"),Catalog!B:B),"")} -> LASDOPPEN 12-24 mm | E20: 220 | K20: 1650 STUCKS
B21: 30-01-2026 | C21: 0575 | D21: {=IFERROR(_xlfn.XLOOKUP(TEXT(C21,"0000"),TEXT(Catalog!A:A,"0000"),Catalog!B:B),"")} -> LASDOPPEN 3.0-12.5 mm | E21: 100 | K21: 5000 STUCKS
B22: 30-01-2026 | C22: 0576 | D22: {=IFERROR(_xlfn.XLOOKUP(TEXT(C22,"0000"),TEXT(Catalog!A:A,"0000"),Catalog!B:B),"")} -> LASDOPPEN 7.5-18.0 mm | E22: 80 | K22: 2400 STUCKS
B23: 30-01-2026 | C23: 7176 | D23: {=IFERROR(_xlfn.XLOOKUP(TEXT(C23,"0000"),TEXT(Catalog!A:A,"0000"),Catalog!B:B),"")} -> INSTEEK FLEXIBLE CLE54 | E23: 60
B24: 30-01-2026 | C24: 0569 | D24: {=IFERROR(_xlfn.XLOOKUP(TEXT(C24,"0000"),TEXT(Catalog!A:A,"0000"),Catalog!B:B),"")} -> CONEX STEEKKLEM 3-VOUDIG | E24: 160 | K24: 12000 STUCKS
B25: 30-01-2026 | C25: 0570 | D25: {=IFERROR(_xlfn.XLOOKUP(TEXT(C25,"0000"),TEXT(Catalog!A:A,"0000"),Catalog!B:B),"")} -> CONEX STEEKKLEM 4-VOUDIG | E25: 160 | K25: 12000 STUCKS
B26: 30-01-2026 | C26: 0571 | D26: {=IFERROR(_xlfn.XLOOKUP(TEXT(C26,"0000"),TEXT(Catalog!A:A,"0000"),Catalog!B:B),"")} -> CONEX STEEKKLEM 5-VOUDIG | E26: 140 | K26: 10500 STUCKS
B27: 30-01-2026 | C27: 15143 | D27: {=IFERROR(_xlfn.XLOOKUP(TEXT(C27,"0000"),TEXT(Catalog!A:A,"0000"),Catalog!B:B),"")} -> OPB.KAST WD 24MD CDN24PT/RR | E27: 1 | K27: CAJA ROTA HAY OTRAS C10
B29: C3 | I29: Cajas import | J29: Total | K29: Observaciones
B30: Fecha | C30: Código | D30: Referencia | E30: Cajas | F30: Sueltos | G30: Cajas 0x0 | H30: Sueltos | J30: Unidades
B31: 30-01-2026 | C31: 0631 | D31: {=IFERROR(_xlfn.XLOOKUP(TEXT(C31,"0000"),TEXT(Catalog!A:A,"0000"),Catalog!B:B),"")} -> KSV PATRONEN 160A NH 00 | E31: 5X3 | J31: 15
B32: 30-01-2026 | C32: 0630 | D32: {=IFERROR(_xlfn.XLOOKUP(TEXT(C32,"0000"),TEXT(Catalog!A:A,"0000"),Catalog!B:B),"")} -> KSV PATRONEN 125A NH 00 | E32: 17X3 | J32: 51 | K32: CONFIRMAR CODIGO
B33: 30-01-2026 | C33: 0628 | D33: {=IFERROR(_xlfn.XLOOKUP(TEXT(C33,"0000"),TEXT(Catalog!A:A,"0000"),Catalog!B:B),"")} -> KSV PATRONEN 80A NH 00 | E33: 9X9 | F33: 1 | J33: 81
B34: 30-01-2026 | C34: 0627 | D34: {=IFERROR(_xlfn.XLOOKUP(TEXT(C34,"0000"),TEXT(Catalog!A:A,"0000"),Catalog!B:B),"")} -> KSV PATRONEN 63A NH 00 | E34: 5X3 | J34: 15
B35: 30-01-2026 | C35: 0625 | D35: {=IFERROR(_xlfn.XLOOKUP(TEXT(C35,"0000"),TEXT(Catalog!A:A,"0000"),Catalog!B:B),"")} -> KSV PATRONEN 35A NH 00 | E35: 35X3 | J35: 105
B36: 30-01-2026 | C36: 0624 | D36: {=IFERROR(_xlfn.XLOOKUP(TEXT(C36,"0000"),TEXT(Catalog!A:A,"0000"),Catalog!B:B),"")} -> KSV PATRONEN 25A NH 00 | E36: 12X3 | J36: 36
B38: C4 | I38: Cajas import | J38: Total | K38: Observaciones
B39: Fecha | C39: Código | D39: Referencia | E39: Cajas | F39: Sueltos | G39: Cajas 0x0 | H39: Sueltos | J39: Unidades
B40: 30-01-2026 | C40: 1153 | D40: {=IFERROR(_xlfn.XLOOKUP(TEXT(C40,"0000"),TEXT(Catalog!A:A,"0000"),Catalog!B:B),"")} -> DEKSEL INB DOOS AM 4x4" 2-VOUD | E40: 15x50 | J40: 750
B41: 30-01-2026 | C41: 15140 | D41: {=IFERROR(_xlfn.XLOOKUP(TEXT(C41,"0000"),TEXT(Catalog!A:A,"0000"),Catalog!B:B),"")} -> OPB.KAST WD 12MD CDN12PT/RR | E41: 21 | J41: 21
B42: 30-01-2026 | C42: 1152 | D42: {=IFERROR(_xlfn.XLOOKUP(TEXT(C42,"0000"),TEXT(Catalog!A:A,"0000"),Catalog!B:B),"")} -> DEKSEL INB DOOS AM 4x4" 4150 | E42: 55x50 + 12x50 | J42: =2750+600 -> 3350 | K42: 55 modelo viejo 12 modelo nuevo
B43: 30-01-2026 | C43: 3332 | D43: {=IFERROR(_xlfn.XLOOKUP(TEXT(C43,"0000"),TEXT(Catalog!A:A,"0000"),Catalog!B:B),"")} -> PICKENS 18 WATT 6500K LED SPOT | E43: 3x8 | J43: 24
B44: 30-01-2026 | C44: 1375 | D44: {=IFERROR(_xlfn.XLOOKUP(TEXT(C44,"0000"),TEXT(Catalog!A:A,"0000"),Catalog!B:B),"")} -> RAWPLUGS WIT (5x25mm-1") | E44: 120 | K44: 30boxes 600frames 15000pcs
...

Sheet D1 (M)
B1: Deposito Nro 1
B2: A-1 | I2: Cajas import | J2: Total | K2: Observaciones
B3: Fecha | C3: Código | D3: Referencia | E3: Cajas | F3: Sueltos | G3: Cajas 0x0 | H3: Sueltos | J3: Unidades
B4: 26-01-26 | C4: 3229 | D4: TL-ORNEMENT LED 1x18W WD LEEG | E4: 81
B7: A-2 | I7: Cajas import | J7: Total | K7: Observaciones
B8: Fecha | C8: Código | D8: Referencia | E8: Cajas | F8: Sueltos | G8: Cajas 0x0 | H8: Sueltos | J8: Unidades
B9: 26-01-26 | C9: 0103 | D9: VD DRAAD 2.5 mm BLAUW | E9: 489
B12: A-3 | I12: Cajas import | J12: Total | K12: Observaciones
B13: Fecha | C13: Código | D13: Referencia | E13: Cajas | F13: Sueltos | G13: Cajas 0x0 | H13: Sueltos | J13: Unidades
B14: 26-01-26 | C14: 0101 | D14: VD DRAAD 1.5 mm ZWART | E14: 291
B17: A-4 | I17: Cajas import | J17: Total | K17: Observaciones
B18: Fecha | C18: Código | D18: Referencia | E18: Cajas | F18: Sueltos | G18: Cajas 0x0 | H18: Sueltos | J18: Unidades
B19: 26-01-26 | C19: 3231 | D19: TL ORNEMENT LED2X18W WD LEEG | E19: 59
B22: A-5 | I22: Cajas import | J22: Total | K22: Observaciones
B23: Fecha | C23: Código | D23: Referencia | E23: Cajas | F23: Sueltos | G23: Cajas 0x0 | H23: Sueltos | J23: Unidades
B24: 26-01-26 | C24: 3258 | D24: LED TUBE 10W 4000K 60cm | E24: 6 | F24: 11
B25: 26-01-26 | C25: 3225 | D25: TL-ORNEMENT 1x20W WD 127/220V | E25: 2
B26: 26-01-26 | C26: 3275 | D26: LED TUBE T8 10W/865 1050l 6500 | E26: 2
B27: 26-01-26 | C27: 3256 | D27: TL-BUIS LED 10W 6500K | E27: 1
B28: 26-01-26 | C28: 3231 | D28: TL ORNEMENT LED2X18W WD LEEG | E28: 43
B29: 26-01-26 | C29: 3350 | D29: LEDPANEL 40W 2x2 CCT 120-277V | E29: 15
B34: A-6 | I34: Cajas import | J34: Total | K34: Observaciones
B35: Fecha | C35: Código | D35: Referencia | E35: Cajas | F35: Sueltos | G35: Cajas 0x0 | H35: Sueltos | J35: Unidades
A36: CODIGO? | B36: 26-01-26 | C36: 01?? | D36: Amarillas | E36: 280
C37: 3100 | D37: PANEL LED BACKLIT 2X2-40W | E37: 3x4 | F37: 4
B39: B2 | I39: Cajas import | J39: Total | K39: Observaciones
B40: Fecha | C40: Código | D40: Referencia | E40: Cajas | F40: Sueltos Unidades | G40: Cajas 0x0 | H40: Sueltos cajas | J40: Unidades
B41: 23-01-26 | C41: 3210 | D41: TL-ORNEMENT 1x20W 127/220V | E41: 10 | F41: 3
B42: 23-01-26 | C42: 3230 | D42: TL ORNEMENT LED 2X9W WD LEEG | E42: 66+24
B43: 23-01-26 | C43: 3224 | D43: TL ORNEMENT LED 1X18W LEEG | E43: 11 | F43: 4
B44: 26-01-26 | D44: Rema 212.430 Bi-metallic tap-off clamp | E44: 1 | F44: 4
B47: B3 | I47: Cajas import | J47: Total | K47: Observaciones
B48: Fecha | C48: Código | D48: Referencia | E48: Cajas | F48: Sueltos Unidades | G48: Cajas 0x0 | H48: Sueltos cajas | J48: Unidades
B49: 23-01-26 | C49: 0102 | D49: VD DRAAD 2.5 mm BRUIN | E49: 426
B50: 23-01-26 | D50: Fluorescent Fitting | E50: 7 | F50: 8
B51: 23-01-26 | C51: 4102 | D51: TRIPLE ROCKERS 90661 TBR
B52: 23-01-26 | C52: 4142 | D52: TRIPLE ROCKERS 90661 TPM | E52: 19
B53: 23-01-26 | C53: 4105 | D53: COVER PLATE SINGLE RJ45 90751
B54: 23-01-26 | C54: 4144 | D54: COV PLATE SINGLE RJ45 90751TPM
B55: 23-01-26 | C55: 90106 | D55: COV PLATE SINGL RJ45 90751TAL | E55: 17
...

Sheet Sheet1
A1: A-2 | F1: Total | G1: Observaciones
A2: Fecha | B2: Código | C2: Referencia | D2: Cajas | E2: Sueltos | F2: Unidades
A3: 26-01-26 | B3: 0103 | C3: VD DRAAD 2.5 mm BLAUW | D3: 489

Sheet D2 (M)
B1: Deposito Nro 2
B2: B-1 | I2: Cajas import | J2: Total | K2: Observaciones
B3: Fecha | C3: Código | D3: Referencia | E3: Cajas | F3: Sueltos | G3: Cajas 0x0 | H3: Sueltos | J3: Unidades
B4: 27-01-26 | C4: 1769 | D4: ETI AUTOMAAT6KA B40 1P B KAR | E4: 28
B5: 27-01-26 | C5: 1742 | D5: ETI AUTOMAAT6KA 32A 1P+N CKAR | E5: 1x9
B6: 27-01-26 | C6: 1715 | D6: ETI AUTOMAAT 6KA 1P+N 25A B | E6: 4
B7: 27-01-26 | C7: 1713 | D7: ETI AUTOMAAT6KA 25A 1P+N CKAR | E7: 10
B8: 27-01-26 | C8: 1712 | D8: ETI AUTOMAAT6KA 20A 1P+N CKAR | E8: 10 | F8: 10
B9: 27-01-26 | C9: 1711 | D9: ETI AUTOMAAT6KA 16A 1P+N CKAR
B10: 27-01-26 | C10: 1737 | D10: ETI AUTOMAAT 6KA 3P+N 6A BKAR | E10: 2
B11: 27-01-26 | C11: 1709 | D11: ETI AUTOMAAT6KA 6A 1P+N BKAR | E11: 1 | F11: 5
B12: 27-01-26 | C12: 8031 | D12: ETI aardleksch 40A 4P0,03 127V | E12: 19
B13: 27-01-26 | C13: 1711 | D13: ETI AUTOMAAT6KA 16A 1P+N CKAR | E13: 22
B14: 27-01-26 | C14: 1710 | D14: ETI AUTOMAAT6KA 16A 1P+N BKAR | E14: 44 | F14: 6
B16: 28-01-26 | C16: 1972 | D16: SCHAKELAAR MESPATR INB 630A | E16: 1
B17: 28-01-27 | C17: 1995 | D17: OMSCHAKELAAR 160A 3P+N | E17: 5
B18: 28-01-28 | C18: 1954 | D18: OMSCHAKELAAR 63A 3P+N | E18: 13
B19: 28-01-29 | C19: 1958 | D19: OMSCHAKELAAR 250A 3P+N | E19: 7
B20: 28-01-30 | C20: 1937 | D20: HOOFDSCHAKELAAR 400A | E20: 7
B23: B-2 | I23: Cajas import | J23: Total | K23: Observaciones
B24: Fecha | C24: Código | D24: Referencia | E24: Cajas | F24: Sueltos | G24: Cajas 0x0 | H24: Sueltos | J24: Unidades
B25: 27-01-26 | C25: 7038 | D25: JVM 65-125 125A 3P+N C-TYPE | E25: 15
B26: 27-01-26 | C26: 7037 | D26: JVM 65-125 100A 3P+N C-TYPE | E26: 11
B27: 27-01-26 | C27: 1738 | D27: ETI AUTOMAAT 6KA 3P+N 6A CKAR | E27: 1 | F27: 2
B28: 27-01-26 | C28: 1728 | D28: ETI AUTOMAAT 6KA 3P+N 16A CKAR | E28: 29 | F28: 2
B29: 27-01-26 | C29: 1740 | D29: ETI AUTOMAAT 6KA 2P 40A CKAR | E29: 6 | F29: 5
B30: 27-01-26 | C30: 1739 | D30: ETI AUTOMAAT 6KA 2P 32A CKAR | E30: 7 | F30: 1
B31: 27-01-26 | C31: 1719 | D31: ETI AUTOMAAT 6KA 2P 25A CKAR | E31: 10
B32: 27-01-26 | C32: 1718 | D32: ETI AUTOMAAT 6KA 2P 20A CKAR | E32: 3 | F32: 5
B34: 27-01-26 | C34: 1727 | D34: ETI AUTOMAAT 6KA 3P+N 16A BKAR | E34: 2
B35: 27-01-26 | C35: 1717 | D35: ETI AUTOMAAT 6KA 2P 16A B KAR | E35: 20
B36: 27-01-26 | C36: 1788 | D36: ETI 4804051 KWH METER 3X63A D | E36: 2
B38: 28-01-26 | C38: 15? | F38: 1
B39: 28-01-26 | C39: 1574 | D39: GE AUTOMAAT 100A, 3P+N C KAR | E39: 4x2
B40: 28-01-26 | C40: 1571 | D40: GE AUTOMAAT 50A, 3P+N C-KAR | E40: 10x3
B41: 28-01-26 | C41: 1570 | D41: GE AUTOMAAT 40A, 3P+N C-KAR | E41: 13x3 | F41: 2
B42: 28-01-26 | C42: 1569 | D42: GE AUTOMAAT 32A, 3P+N C-KAR | E42: 2x3 | F42: 2
B43: 28-01-26 | C43: 1577 | D43: GE AUTOMAAT 20A, 3P+N C-KAR | E43: 5x3
B44: 28-01-26 | C44: 1523 | D44: GE AUTO 25A, 4P-2MOD C UNIBIS | E44: 13x6 | F44: 3
B45: 28-01-26 | C45: 1576 | D45: GE AUTOMAAT 16A, 3P+N C-KAR | E45: 2x3 | F45: 1
...

Sheet D3 (M)
B1: Deposito Nro 3
B2: A1 | I2: Cajas import | J2: Total | K2: Observaciones
B3: Fecha | C3: Código | D3: Referencia | E3: Cajas | F3: Sueltos | G3: Cajas 0x0 | H3: Sueltos | J3: Unidades
B4: 29-01-2026 | C4: 1236 | D4: {=IFERROR(_xlfn.XLOOKUP(TEXT(C4,"0000"),TEXT(Catalog!A:A,"0000"),Catalog!B:B),"")} -> CONTRA STEK R/A RUBBER HSKP16G | E4: 6
B5: 29-01-2026 | C5: 1196 | D5: {=IFERROR(_xlfn.XLOOKUP(TEXT(C5,"0000"),TEXT(Catalog!A:A,"0000"),Catalog!B:B),"")} -> WCD EUR ENK R/A OPB WD KOPP | E5: 11
B6: 29-01-2026 | C6: 7158 | D6: {=IFERROR(_xlfn.XLOOKUP(TEXT(C6,"0000"),TEXT(Catalog!A:A,"0000"),Catalog!B:B),"")} -> OPB.STOPCONTACT WD 3160 | E6: 17 | J6: 24
B7: 29-01-2026 | C7: 3252 | D7: {=IFERROR(_xlfn.XLOOKUP(TEXT(C7,"0000"),TEXT(Catalog!A:A,"0000"),Catalog!B:B),"")} -> U-BUIS 40W DL | E7: 1X20 | F7: 4
B8: 29-01-2026 | C8: 493 | D8: {=IFERROR(_xlfn.XLOOKUP(TEXT(C8,"0000"),TEXT(Catalog!A:A,"0000"),Catalog!B:B),"")} -> KABELDOOS EP088 (18100) | E8: 184
B9: 29-01-2026 | C9: 15141 | D9: {=IFERROR(_xlfn.XLOOKUP(TEXT(C9,"0000"),TEXT(Catalog!A:A,"0000"),Catalog!B:B),"")} -> OPBOUW KAST WD CS13PT/RR | E9: 4
B10: 29-01-2026 | C10: 7163 | D10: {=IFERROR(_xlfn.XLOOKUP(TEXT(C10,"0000"),TEXT(Catalog!A:A,"0000"),Catalog!B:B),"")} -> TERMOPLASTIC STEKKER 6428 WIT | E10: 405
B11: 29-01-2026 | C11: 7164 | D11: {=IFERROR(_xlfn.XLOOKUP(TEXT(C11,"0000"),TEXT(Catalog!A:A,"0000"),Catalog!B:B),"")} -> TERMOPLASTIC CONTRA 6707B WIT | E11: 31
B12: 29-01-2026 | C12: 7165 | D12: {=IFERROR(_xlfn.XLOOKUP(TEXT(C12,"0000"),TEXT(Catalog!A:A,"0000"),Catalog!B:B),"")} -> TERMOPLASTIC CONTRA 6707CN | E12: 31
B13: 29-01-2026 | C13: 7160 | D13: {=IFERROR(_xlfn.XLOOKUP(TEXT(C13,"0000"),TEXT(Catalog!A:A,"0000"),Catalog!B:B),"")} -> RUBBER STEKKER 5706C | E13: 17
B14: 29-01-2026 | C14: 7166 | D14: {=IFERROR(_xlfn.XLOOKUP(TEXT(C14,"0000"),TEXT(Catalog!A:A,"0000"),Catalog!B:B),"")} -> TERMOPLASTIC CONTRA 5019 | E14: 9
B15: 29-01-2026 | C15: 7173 | D15: {=IFERROR(_xlfn.XLOOKUP(TEXT(C15,"0000"),TEXT(Catalog!A:A,"0000"),Catalog!B:B),"")} -> TERMOPLASTIC ZIJK STEKKER 6566 | E15: 15
B16: 29-01-2026 | C16: 0494 | D16: {=IFERROR(_xlfn.XLOOKUP(TEXT(C16,"0000"),TEXT(Catalog!A:A,"0000"),Catalog!B:B),"")} -> KABELDOOS EV111(18300) | E16: 2X85 | F16: 44
B19: A2 | I19: Cajas import | J19: Total | K19: Observaciones
B20: Fecha | C20: Código | D20: Referencia | E20: Cajas | F20: Sueltos | G20: Cajas 0x0 | H20: Sueltos | J20: Unidades
B21: 29-01-2026 | C21: 1223 | D21: {=IFERROR(_xlfn.XLOOKUP(TEXT(C21,"0000"),TEXT(Catalog!A:A,"0000"),Catalog!B:B),"")} -> KOPP WCD EUR DUB R/AOPB 74108 | E21: 8+4
B22: 29-01-2026 | C22: 7071 | D22: {=IFERROR(_xlfn.XLOOKUP(TEXT(C22,"0000"),TEXT(Catalog!A:A,"0000"),Catalog!B:B),"")} -> ADER EINDHULS 2.5mm E2508 | E22: 5
B23: 29-01-2026 | C23: 7080 | D23: {=IFERROR(_xlfn.XLOOKUP(TEXT(C23,"0000"),TEXT(Catalog!A:A,"0000"),Catalog!B:B),"")} -> ADER EINDHULS 2X2.5mm TE2510 | E23: 22
B24: 29-01-2026 | C24: 7072 | D24: {=IFERROR(_xlfn.XLOOKUP(TEXT(C24,"0000"),TEXT(Catalog!A:A,"0000"),Catalog!B:B),"")} -> ADER EINDHULS 4mm E4012 | E24: 14
B25: 30-01-2026 | C25: 7081 | D25: {=IFERROR(_xlfn.XLOOKUP(TEXT(C25,"0000"),TEXT(Catalog!A:A,"0000"),Catalog!B:B),"")} -> ADER EINDHULS 2X4mm TE4012 | E25: 6
B26: 30-01-2026 | C26: 7070 | D26: {=IFERROR(_xlfn.XLOOKUP(TEXT(C26,"0000"),TEXT(Catalog!A:A,"0000"),Catalog!B:B),"")} -> ADER EINDHULS 1.5mm E1508 | F26: 29
B27: 30-01-2026 | C27: 7079 | D27: {=IFERROR(_xlfn.XLOOKUP(TEXT(C27,"0000"),TEXT(Catalog!A:A,"0000"),Catalog!B:B),"")} -> ADER EINDHULS 2X1.5mm TE1508 | E27: 3X3000
B28: 30-01-2026 | C28: 7073 | D28: {=IFERROR(_xlfn.XLOOKUP(TEXT(C28,"0000"),TEXT(Catalog!A:A,"0000"),Catalog!B:B),"")} -> ADER EINDHULS 6mm E6012 | E28: 1X1000
B29: 30-01-2026 | C29: 1161 | D29: {=IFERROR(_xlfn.XLOOKUP(TEXT(C29,"0000"),TEXT(Catalog!A:A,"0000"),Catalog!B:B),"")} -> PHOTOCEL 220 VOLT A-1068W | E29: 42
B30: 30-01-2026 | C30: 7083 | D30: {=IFERROR(_xlfn.XLOOKUP(TEXT(C30,"0000"),TEXT(Catalog!A:A,"0000"),Catalog!B:B),"")} -> ADER EINDHULS 2X10mm TE1014 | E30: 22
B31: 30-01-2026 | C31: 1216 | D31: {=IFERROR(_xlfn.XLOOKUP(TEXT(C31,"0000"),TEXT(Catalog!A:A,"0000"),Catalog!B:B),"")} -> TREKKOORTJE 1,9 mtr | E31: 93
B32: 30-01-2026 | C32: 7177 | D32: {=IFERROR(_xlfn.XLOOKUP(TEXT(C32,"0000"),TEXT(Catalog!A:A,"0000"),Catalog!B:B),"")} -> LAMPHOUDER 6511/75 | E32: 7
B33: 30-01-2026 | C33: 1218 | D33: {=IFERROR(_xlfn.XLOOKUP(TEXT(C33,"0000"),TEXT(Catalog!A:A,"0000"),Catalog!B:B),"")} -> TIMER 250V/50Hz WHITE | E33: 7
B34: 30-01-2026 | C34: 3119 | D34: {=IFERROR(_xlfn.XLOOKUP(TEXT(C34,"0000"),TEXT(Catalog!A:A,"0000"),Catalog!B:B),"")} -> SURGE PROTECTOR 127V USB | E34: 21
B35: 30-01-2026 | C35: 1237 | D35: {=IFERROR(_xlfn.XLOOKUP(TEXT(C35,"0000"),TEXT(Catalog!A:A,"0000"),Catalog!B:B),"")} -> VERLOOP STEKKER PEN PL 695 | E35: 1X100
B36: 30-01-2026 | C36: 1242 | D36: {=IFERROR(_xlfn.XLOOKUP(TEXT(C36,"0000"),TEXT(Catalog!A:A,"0000"),Catalog!B:B),"")} -> VERLOOP STEKKER PEN RO 686 | E36: 4
B37: 30-01-2026 | C37: 1593 | D37: {=IFERROR(_xlfn.XLOOKUP(TEXT(C37,"0000"),TEXT(Catalog!A:A,"0000"),Catalog!B:B),"")} -> Terminal bar 2x16mm6x6mm610314 | K37: Bolsa con tornillos
B38: 30-01-2026 | C38: 7084 | D38: {=IFERROR(_xlfn.XLOOKUP(TEXT(C38,"0000"),TEXT(Catalog!A:A,"0000"),Catalog!B:B),"")} -> ADER EINDHULS 2X16mm TE1614 | E38: 100
B39: 30-01-2026 | C39: 7076 | D39: {=IFERROR(_xlfn.XLOOKUP(TEXT(C39,"0000"),TEXT(Catalog!A:A,"0000"),Catalog!B:B),"")} -> ADER EINDHULS 25mm E2516 | E39: 33
B40: 30-01-2026 | C40: 7077 | D40: {=IFERROR(_xlfn.XLOOKUP(TEXT(C40,"0000"),TEXT(Catalog!A:A,"0000"),Catalog!B:B),"")} -> ADER EINDHULS 35mm E3516 | E40: 44x200
B41: 30-01-2026 | C41: 7078 | D41: {=IFERROR(_xlfn.XLOOKUP(TEXT(C41,"0000"),TEXT(Catalog!A:A,"0000"),Catalog!B:B),"")} -> ADER EINDHULS 50mm E5020 | E41: 41x100
B42: 30-01-2026 | C42: 1223 | D42: {=IFERROR(_xlfn.XLOOKUP(TEXT(C42,"0000"),TEXT(Catalog!A:A,"0000"),Catalog!B:B),"")} -> KOPP WCD EUR DUB R/AOPB 74108 | E42: 7
...

Sheet D4 (M)
B1: Deposito Nro 4
B2: ? | I2: Cajas import | J2: Total | K2: Observaciones | M2: IFERROR(XLOOKUP(TEXT(C4,"0000"),TEXT(Catalog!A:A,"0000"),Catalog!B:B),"")
B3: Fecha | C3: Código | D3: Referencia | E3: Cajas | F3: Sueltos | G3: Cajas 0x0 | H3: Sueltos | J3: Unidades | M3: XLOOKUP(TRIM(CLEAN(TEXT(C4,"@"))),TRIM(CLEAN(Catalog!A:A)),Catalog!B:B)
B4: 46083 | C4: 3322 | D4: {=IFERROR(_xlfn.XLOOKUP(TEXT(C4,"0000"),TEXT(Catalog!A:A,"0000"),Catalog!B:B),"")} -> PICKENS RECHARGEABLE LED LIGHT | F4: 36
B5: 46083 | C5: 1652 | D5: {=IFERROR(_xlfn.XLOOKUP(TEXT(C5,"0000"),TEXT(Catalog!A:A,"0000"),Catalog!B:B),"")} -> IDE AARDE 48452 KIT TIERRA | F5: 6
B6: 46083 | C6: 7187 | D6: {=IFERROR(_xlfn.XLOOKUP(TEXT(C6,"0000"),TEXT(Catalog!A:A,"0000"),Catalog!B:B),"")} -> INB.KAST MP56 METALBOX
B7: 46083 | C7: 1654 | D7: {=IFERROR(_xlfn.XLOOKUP(TEXT(C7,"0000"),TEXT(Catalog!A:A,"0000"),Catalog!B:B),"")} -> OPBOUWKAST IDE ARM.40COM120 | E7: 7X1
D8: )
B9: A1 | I9: Cajas import | J9: Total | K9: Observaciones
B10: Fecha | C10: Código | D10: Referencia | E10: Cajas | F10: Sueltos | G10: Cajas 0x0 | H10: Sueltos | J10: Unidades
B11: 46083 | C11: 0560 | D11: {=IFERROR(_xlfn.XLOOKUP(TEXT(C11,"0000"),TEXT(Catalog!A:A,"0000"),Catalog!B:B),"")} -> MOER PG 13,5 | F11: 94X50
B12: 46083 | C12: 0550 | D12: {=IFERROR(_xlfn.XLOOKUP(TEXT(C12,"0000"),TEXT(Catalog!A:A,"0000"),Catalog!B:B),"")} -> PG 13,5 + MOER | F12: 31X50
B14: A2 | I14: Cajas import | J14: Total | K14: Observaciones
B15: Fecha | C15: Código | D15: Referencia | E15: Cajas | F15: Sueltos | G15: Cajas 0x0 | H15: Sueltos | J15: Unidades
B16: 46083 | C16: 12431 | D16: {=IFERROR(_xlfn.XLOOKUP(TEXT(C16,"0000"),TEXT(Catalog!A:A,"0000"),Catalog!B:B),"")} -> CEE-FORM STEKKER 2P+E16A-02101 | E16: 1x12 | F16: 5
B17: 46083 | C17: 1249 | D17: {=IFERROR(_xlfn.XLOOKUP(TEXT(C17,"0000"),TEXT(Catalog!A:A,"0000"),Catalog!B:B),"")} -> CEE-FOR STEK 2P+E16A IP67-2601 | E17: 5x6 | F17: 3
B18: 46083 | C18: 1246 | D18: {=IFERROR(_xlfn.XLOOKUP(TEXT(C18,"0000"),TEXT(Catalog!A:A,"0000"),Catalog!B:B),"")} -> CEE-FORM STEK 2P+E 32A-02104 | E18: 5x8
B19: 46083 | C19: 12521 | D19: {=IFERROR(_xlfn.XLOOKUP(TEXT(C19,"0000"),TEXT(Catalog!A:A,"0000"),Catalog!B:B),"")} -> CEE-FORM STEK 2P+E 32A 02604 | E19: 2x5 | F19: 2
B20: 46083 | C20: 12441 | D20: {=IFERROR(_xlfn.XLOOKUP(TEXT(C20,"0000"),TEXT(Catalog!A:A,"0000"),Catalog!B:B),"")} -> CEE-FORM STEKKER 3P+E16A-03102 | E20: 1x10 | F20: 8
B21: 46083 | C21: 12451 | D21: {=IFERROR(_xlfn.XLOOKUP(TEXT(C21,"0000"),TEXT(Catalog!A:A,"0000"),Catalog!B:B),"")} -> CEE-FORM STEK 3P+N+E 16A-03103 | E21: 3x10 | F21: 1
B22: 46083 | C22: 1247 | D22: {=IFERROR(_xlfn.XLOOKUP(TEXT(C22,"0000"),TEXT(Catalog!A:A,"0000"),Catalog!B:B),"")} -> CEE-FORM STEK 3P+E 32A-03105 | E22: 1x8 | F22: 4
B23: 46083 | C23: 1248 | D23: {=IFERROR(_xlfn.XLOOKUP(TEXT(C23,"0000"),TEXT(Catalog!A:A,"0000"),Catalog!B:B),"")} -> CEE-FORM STEK 3P+N+E 32A-03106 | E23: 3x10
B24: 46083 | C24: 12501 | D24: {=IFERROR(_xlfn.XLOOKUP(TEXT(C24,"0000"),TEXT(Catalog!A:A,"0000"),Catalog!B:B),"")} -> CEE-FOR STEK3P+E 16A IP67 3602 | E24: 5x6 | F24: 2
B26: A3 | I26: Cajas import | J26: Total | K26: Observaciones
B27: Fecha | C27: Código | D27: Referencia | E27: Cajas | F27: Sueltos | G27: Cajas 0x0 | H27: Sueltos | J27: Unidades
B28: 46083 | C28: 12541 | D28: {=IFERROR(_xlfn.XLOOKUP(TEXT(C28,"0000"),TEXT(Catalog!A:A,"0000"),Catalog!B:B),"")} -> CEE-FORM -WCD 2P+E 16A-02321 | E28: 1x10 | F28: 6
B29: 46083 | C29: 12601 | D29: {=IFERROR(_xlfn.XLOOKUP(TEXT(C29,"0000"),TEXT(Catalog!A:A,"0000"),Catalog!B:B),"")} -> CEE-FORM WCD 2P+E 16A -02821 | E29: 3x6 | F29: 5
B30: 46083 | C30: 12551 | D30: {=IFERROR(_xlfn.XLOOKUP(TEXT(C30,"0000"),TEXT(Catalog!A:A,"0000"),Catalog!B:B),"")} -> CEE-FORM WCD 3P+E 16A-03322 | E30: 2x10
B31: 46083 | C31: 12603 | D31: {=IFERROR(_xlfn.XLOOKUP(TEXT(C31,"0000"),TEXT(Catalog!A:A,"0000"),Catalog!B:B),"")} -> CEE-FORM WCD 3P+N+E 16A 03823 | F31: 2
B32: 46083 | C32: 12602 | D32: {=IFERROR(_xlfn.XLOOKUP(TEXT(C32,"0000"),TEXT(Catalog!A:A,"0000"),Catalog!B:B),"")} -> CEE-FORM WCD 3P+E 16A -03822 | E32: 1x5 | F32: 3
B33: 46083 | C33: 12561 | D33: {=IFERROR(_xlfn.XLOOKUP(TEXT(C33,"0000"),TEXT(Catalog!A:A,"0000"),Catalog!B:B),"")} -> CEE-FORM WCD 3P+N+E 16A-03323 | E33: 1x10 | F33: 7
B35: A4 | I35: Cajas import | J35: Total | K35: Observaciones
B36: Fecha | C36: Código | D36: Referencia | E36: Cajas | F36: Sueltos | G36: Cajas 0x0 | H36: Sueltos | J36: Unidades
B37: 46083 | C37: 12533 | D37: {=IFERROR(_xlfn.XLOOKUP(TEXT(C37,"0000"),TEXT(Catalog!A:A,"0000"),Catalog!B:B),"")} -> CEE-FORM STEK 3P+E 63A 03652 | E37: 11x2 | F37: 1
B38: 46083 | C38: 1277 | D38: {=IFERROR(_xlfn.XLOOKUP(TEXT(C38,"0000"),TEXT(Catalog!A:A,"0000"),Catalog!B:B),"")} -> CEE-FORM CONN 3P+E 63A 03752 | E38: 9x2 | F38: 1
B40: A5 | I40: Cajas import | J40: Total | K40: Observaciones
B41: Fecha | C41: Código | D41: Referencia | E41: Cajas | F41: Sueltos | G41: Cajas 0x0 | H41: Sueltos | J41: Unidades
B42: 46083 | C42: 0554 | D42: {=IFERROR(_xlfn.XLOOKUP(TEXT(C42,"0000"),TEXT(Catalog!A:A,"0000"),Catalog!B:B),"")} -> PG 36 | E42: 21x10
B43: 46083 | C43: 0565 | D43: {=IFERROR(_xlfn.XLOOKUP(TEXT(C43,"0000"),TEXT(Catalog!A:A,"0000"),Catalog!B:B),"")} -> MOER PG 48 | E43: 42x5 y 9x10 | K43: Complemento y tuerca
B44: 46083 | C44: 0547 | D44: {=IFERROR(_xlfn.XLOOKUP(TEXT(C44,"0000"),TEXT(Catalog!A:A,"0000"),Catalog!B:B),"")} -> PG+MOER M16 | E44: 13x50
...

Sheet D1 (V) Fixed
D1: Deposito Nro 1
D2: B-4 | L2: Total
A3: counter_name | B3: deposit_id | C3: rack_id | D3: count_date | E3: codeitem | F3: Referencia | G3: boxqty | H3: boxunitqty | I3: boxunittotal | J3: magazijn | K3: winkel | L3: total
A4: VICTORIA | B4: 1 | C4: 16 | D4: 26-01-2026 | E4: 4040 | F4: {=IFERROR(_xlfn.XLOOKUP(TEXT(E4,"0000"),TEXT(Catalog!A:A,"0000"),Catalog!B:B),"")} -> SINGLE POLE SWITCH 37011 OPB | G4: 2 | H4: 100 | I4: =G4*H4 -> 200 | J4: 1 | K4: 0 | L4: =I4+J4+K4 -> 201
A5: VICTORIA | B5: 1 | C5: 16 | D5: 26-01-2026 | E5: 4042 | F5: {=IFERROR(_xlfn.XLOOKUP(TEXT(E5,"0000"),TEXT(Catalog!A:A,"0000"),Catalog!B:B),"")} -> TWO-WAY SWITCH 37071 OPB | G5: 24 | H5: 1 | I5: =G5*H5 -> 24 | J5: 0 | K5: 0 | L5: =I5+J5+K5 -> 24
A6: VICTORIA | B6: 1 | C6: 16 | D6: 26-01-2026 | E6: 4041 | F6: {=IFERROR(_xlfn.XLOOKUP(TEXT(E6,"0000"),TEXT(Catalog!A:A,"0000"),Catalog!B:B),"")} -> TWO CIRCUITS SWITCH 37061 OPB | G6: 31 | H6: 1 | I6: =G6*H6 -> 31 | J6: 0 | K6: 0 | L6: =I6+J6+K6 -> 31
A7: VICTORIA | B7: 1 | C7: 16 | D7: 26-01-2026 | E7: 4043 | F7: {=IFERROR(_xlfn.XLOOKUP(TEXT(E7,"0000"),TEXT(Catalog!A:A,"0000"),Catalog!B:B),"")} -> DOUBLE 2-WAY SWITCH 37101 OPB | G7: 15 | H7: 1 | I7: =G7*H7 -> 15 | J7: 0 | K7: 0 | L7: =I7+J7+K7 -> 15
A8: VICTORIA | B8: 1 | C8: 16 | D8: 26-01-2026 | E8: 4050 | F8: {=IFERROR(_xlfn.XLOOKUP(TEXT(E8,"0000"),TEXT(Catalog!A:A,"0000"),Catalog!B:B),"")} -> EARTH SOCKET 48131 OPB WD | G8: 3 | H8: 1 | I8: =G8*H8 -> 3 | J8: 0 | K8: 0 | L8: =I8+J8+K8 -> 3
A9: VICTORIA | B9: 1 | C9: 16 | D9: 26-01-2026 | E9: 4046 | F9: {=IFERROR(_xlfn.XLOOKUP(TEXT(E9,"0000"),TEXT(Catalog!A:A,"0000"),Catalog!B:B),"")} -> SINGLE POLE SWITCH 48011 OP WD | G9: 11 | H9: 1 | I9: =G9*H9 -> 11 | J9: 0 | K9: 0 | L9: =I9+J9+K9 -> 11
A10: VICTORIA | B10: 1 | C10: 16 | D10: 26-01-2026 | E10: 4049 | F10: {=IFERROR(_xlfn.XLOOKUP(TEXT(E10,"0000"),TEXT(Catalog!A:A,"0000"),Catalog!B:B),"")} -> TWO WAY SWITCH 48071 OPB WD | G10: 7 | H10: 1 | I10: =G10*H10 -> 7 | J10: 0 | K10: 0 | L10: =I10+J10+K10 -> 7
A11: VICTORIA | B11: 1 | C11: 16 | D11: 26-01-2026 | E11: 4047 | F11: {=IFERROR(_xlfn.XLOOKUP(TEXT(E11,"0000"),TEXT(Catalog!A:A,"0000"),Catalog!B:B),"")} -> TWO POLE SWITCH 48021 WD OPB | G11: 7 | H11: 1 | I11: =G11*H11 -> 7 | J11: 0 | K11: 0 | L11: =I11+J11+K11 -> 7
A12: VICTORIA | B12: 1 | C12: 16 | D12: 26-01-2026 | E12: 4048 | F12: {=IFERROR(_xlfn.XLOOKUP(TEXT(E12,"0000"),TEXT(Catalog!A:A,"0000"),Catalog!B:B),"")} -> 2 CIRCUITS SWITCH 48061 OPB WD | G12: 9 | H12: 1 | I12: =G12*H12 -> 9 | J12: 0 | K12: 0 | L12: =I12+J12+K12 -> 9
A13: VICTORIA | B13: 1 | C13: 16 | D13: 26-01-2026 | E13: 4024 | F13: {=IFERROR(_xlfn.XLOOKUP(TEXT(E13,"0000"),TEXT(Catalog!A:A,"0000"),Catalog!B:B),"")} -> COV PL SCHUK SOCKET IP44 70634 | G13: 12 | H13: 1 | I13: =G13*H13 -> 12 | J13: 0 | K13: 0 | L13: =I13+J13+K13 -> 12
A14: VICTORIA | B14: 1 | C14: 16 | D14: 26-01-2026 | E14: 4035 | F14: {=IFERROR(_xlfn.XLOOKUP(TEXT(E14,"0000"),TEXT(Catalog!A:A,"0000"),Catalog!B:B),"")} -> WATERPROOF FRAME IP 44 70961 | G14: 4 | H14: 1 | I14: =G14*H14 -> 4 | J14: 0 | K14: 0 | L14: =I14+J14+K14 -> 4
D16: C-3 | L16: Total
D17: Fecha | E17: Código | F17: Referencia | G17: Cajas | J17: Sueltos | K17: Cajas 0x0 | L17: Unidades
A18: VICTORIA | B18: 1 | C18: 27 | D18: 26-01-2026 | E18: 4106 | F18: {=IFERROR(_xlfn.XLOOKUP(TEXT(E18,"0000"),TEXT(Catalog!A:A,"0000"),Catalog!B:B),"")} -> COVER PLATE - TELEPHONE 90712 | G18: 0 | H18: 1 | I18: =G18*H18 -> 0 | J18: 0 | K18: 0 | L18: =I18+J18+K18 -> 0
A19: VICTORIA | B19: 1 | C19: 27 | D19: 26-01-2026 | E19: 4145 | F19: {=IFERROR(_xlfn.XLOOKUP(TEXT(E19,"0000"),TEXT(Catalog!A:A,"0000"),Catalog!B:B),"")} -> COV PLATE TELEPHONE 90712 TPM | G19: 10 | H19: 1 | I19: =G19*H19 -> 10 | J19: 0 | K19: 0 | L19: =I19+J19+K19 -> 10
A20: VICTORIA | B20: 1 | C20: 27 | D20: 26-01-2026 | E20: 4105 | F20: {=IFERROR(_xlfn.XLOOKUP(TEXT(E20,"0000"),TEXT(Catalog!A:A,"0000"),Catalog!B:B),"")} -> COVER PLATE SINGLE RJ45 90751 | G20: 0 | H20: 1 | I20: =G20*H20 -> 0 | J20: 0 | K20: 0 | L20: =I20+J20+K20 -> 0
A21: VICTORIA | B21: 1 | C21: 27 | D21: 26-01-2026 | E21: 4144 | F21: {=IFERROR(_xlfn.XLOOKUP(TEXT(E21,"0000"),TEXT(Catalog!A:A,"0000"),Catalog!B:B),"")} -> COV PLATE SINGLE RJ45 90751TPM | G21: 0 | H21: 1 | I21: =G21*H21 -> 0 | J21: 0 | K21: 0 | L21: =I21+J21+K21 -> 0
A22: VICTORIA | B22: 1 | C22: 27 | D22: 26-01-2026 | E22: 90106 | F22: {=IFERROR(_xlfn.XLOOKUP(TEXT(E22,"0000"),TEXT(Catalog!A:A,"0000"),Catalog!B:B),"")} -> COV PLATE SINGL RJ45 90751TAL | G22: 4 | H22: 1 | I22: =G22*H22 -> 4 | J22: 0 | K22: 0 | L22: =I22+J22+K22 -> 4
A23: VICTORIA | B23: 1 | C23: 27 | D23: 26-01-2026 | E23: 4103 | F23: {=IFERROR(_xlfn.XLOOKUP(TEXT(E23,"0000"),TEXT(Catalog!A:A,"0000"),Catalog!B:B),"")} -> COVER PLATE PULL CORD 90741 | G23: 18 | H23: 1 | I23: =G23*H23 -> 18 | J23: 0 | K23: 0 | L23: =I23+J23+K23 -> 18
A24: VICTORIA | B24: 1 | C24: 27 | D24: 26-01-2026 | E24: 4112 | F24: {=IFERROR(_xlfn.XLOOKUP(TEXT(E24,"0000"),TEXT(Catalog!A:A,"0000"),Catalog!B:B),"")} -> DOUBLE HORIZONTAL FRAME 90920 | G24: 0 | H24: 1 | I24: =G24*H24 -> 0 | J24: 0 | K24: 0 | L24: =I24+J24+K24 -> 0
A25: VICTORIA | B25: 1 | C25: 27 | D25: 26-01-2026 | E25: 4151 | F25: {=IFERROR(_xlfn.XLOOKUP(TEXT(E25,"0000"),TEXT(Catalog!A:A,"0000"),Catalog!B:B),"")} -> 2 X HORIZONTAL FRAME 90920 TPM | G25: 0 | H25: 1 | I25: =G25*H25 -> 0 | J25: 0 | K25: 0 | L25: =I25+J25+K25 -> 0
A26: VICTORIA | B26: 1 | C26: 27 | D26: 26-01-2026 | E26: 90101 | F26: {=IFERROR(_xlfn.XLOOKUP(TEXT(E26,"0000"),TEXT(Catalog!A:A,"0000"),Catalog!B:B),"")} -> DOUBLE FRAME ALU 90920TAA | G26: 41 | H26: 1 | I26: =G26*H26 -> 41 | J26: 0 | K26: 0 | L26: =I26+J26+K26 -> 41
A27: VICTORIA | B27: 1 | C27: 27 | D27: 26-01-2026 | E27: 4109 | F27: {=IFERROR(_xlfn.XLOOKUP(TEXT(E27,"0000"),TEXT(Catalog!A:A,"0000"),Catalog!B:B),"")} -> COVER PLATE SCHUKO SOCKET90634 | G27: 0 | H27: 1 | I27: =G27*H27 -> 0 | J27: 0 | K27: 0 | L27: =I27+J27+K27 -> 0
A28: VICTORIA | B28: 1 | C28: 27 | D28: 26-01-2026 | E28: 4148 | F28: {=IFERROR(_xlfn.XLOOKUP(TEXT(E28,"0000"),TEXT(Catalog!A:A,"0000"),Catalog!B:B),"")} -> COV PLATE SOCKET IP44 90634TPM | G28: 2 | H28: 1 | I28: =G28*H28 -> 2 | J28: 0 | K28: 0 | L28: =I28+J28+K28 -> 2
A29: VICTORIA | B29: 1 | C29: 27 | D29: 26-01-2026 | E29: 4116 | F29: {=IFERROR(_xlfn.XLOOKUP(TEXT(E29,"0000"),TEXT(Catalog!A:A,"0000"),Catalog!B:B),"")} -> WATERPROOF FRAME IP 44 90961 | G29: 5 | H29: 1 | I29: =G29*H29 -> 5 | J29: 0 | K29: 0 | L29: =I29+J29+K29 -> 5
... A35: VICTORIA | B35: 1 | C35: 27 | D35: 26-01-2026 | E35: 3997 | F35: {=IFERROR(_xlfn.XLOOKUP(TEXT(E35,"0000"),TEXT(Catalog!A:A,"0000"),Catalog!B:B),"")} -> SPEED CONTROLLER 21219 | G35: 13 | H35: 1 | I35: =G35*H35 -> 13 | J35: 0 | K35: 0 | L35: =I35+J35+K35 -> 13
D37: C-4 | L37: Total
D38: Fecha | E38: Código | F38: Referencia | G38: Cajas | J38: Sueltos | K38: Cajas 0x0 | L38: Unidades
A39: VICTORIA | B39: 1 | C39: 28 | D39: 26-01-2026 | E39: 4209 | F39: {=IFERROR(_xlfn.XLOOKUP(TEXT(E39,"0000"),TEXT(Catalog!A:A,"0000"),Catalog!B:B),"")} -> KABELGOOT 75X20MM 10140 CBR | G39: 6 | H39: 1 | I39: =G39*H39 -> 6 | J39: 11 | K39: 0 | L39: =I39+J39+K39 -> 17
A40: VICTORIA | B40: 1 | C40: 28 | D40: 26-01-2026 | E40: 4212 | F40: {=IFERROR(_xlfn.XLOOKUP(TEXT(E40,"0000"),TEXT(Catalog!A:A,"0000"),Catalog!B:B),"")} -> KABELGOOT 90X50MM 10180 RBR | G40: 1 | H40: 1 | I40: =G40*H40 -> 1 | J40: 0 | K40: 0 | L40: =I40+J40+K40 -> 1
A41: VICTORIA | B41: 1 | C41: 28 | D41: 26-01-2026 | E41: 4213 | F41: {=IFERROR(_xlfn.XLOOKUP(TEXT(E41,"0000"),TEXT(Catalog!A:A,"0000"),Catalog!B:B),"")} -> KABELGOOT 180X50MM 10290 RBR | G41: 13 | H41: 1 | I41: =G41*H41 -> 13 | J41: 0 | K41: 0 | L41: =I41+J41+K41 -> 13
A42: VICTORIA | B42: 1 | C42: 28 | D42: 26-01-2026 | E42: 4260 | F42: {=IFERROR(_xlfn.XLOOKUP(TEXT(E42,"0000"),TEXT(Catalog!A:A,"0000"),Catalog!B:B),"")} -> VERLENG 110X50MM 10094 RBR | G42: 0 | H42: 1 | I42: =G42*H42 -> 0 | J42: 13 | K42: 0 | L42: =I42+J42+K42 -> 13
A43: VICTORIA | B43: 1 | C43: 28 | D43: 26-01-2026 | E43: 1496 | F43: {=IFERROR(_xlfn.XLOOKUP(TEXT(E43,"0000"),TEXT(Catalog!A:A,"0000"),Catalog!B:B),"")} -> OPBOUW KAST 2 MOD 610090 | G43: 0 | H43: 1 | I43: =G43*H43 -> 0 | J43: 0 | K43: 0 | L43: =I43+J43+K43 -> 0
A44: VICTORIA | B44: 1 | C44: 28 | D44: 26-01-2026 | E44: 4211 | F44: {=IFERROR(_xlfn.XLOOKUP(TEXT(E44,"0000"),TEXT(Catalog!A:A,"0000"),Catalog!B:B),"")} -> KABELGOOT 110X50MM 10090RBR | G44: 2 | H44: 1 | I44: =G44*H44 -> 2 | J44: 0 | K44: 0 | L44: =I44+J44+K44 -> 2
A45: VICTORIA | B45: 1 | C45: 28 | D45: 26-01-2026 | E45: 4210 | F45: {=IFERROR(_xlfn.XLOOKUP(TEXT(E45,"0000"),TEXT(Catalog!A:A,"0000"),Catalog!B:B),"")} -> KABELGOOT 110X34MM 10080 RBR | G45: 5 | H45: 1 | I45: =G45*H45 -> 5 | J45: 0 | K45: 0 | L45: =I45+J45+K45 -> 5
A46: VICTORIA | B46: 1 | C46: 28 | D46: 26-01-2026 | E46: 4201 | F46: {=IFERROR(_xlfn.XLOOKUP(TEXT(E46,"0000"),TEXT(Catalog!A:A,"0000"),Catalog!B:B),"")} -> KABELGOOT 16X10MM 10020 FBR | G46: 1 | H46: 1 | I46: =G46*H46 -> 1 | J46: 56 | K46: 0 | L46: =I46+J46+K46 -> 57
A47: VICTORIA | B47: 1 | C47: 28 | D47: 26-01-2026 | E47: 4207 | F47: {=IFERROR(_xlfn.XLOOKUP(TEXT(E47,"0000"),TEXT(Catalog!A:A,"0000"),Catalog!B:B),"")} -> KABELGOOT 50X20MM 10500 CBR | G47: 2 | H47: 1 | I47: =G47*H47 -> 2 | J47: 6 | K47: 0 | L47: =I47+J47+K47 -> 8
...

Sheet D2 (V) Fixed
D1: Deposito Nro 2
D2: A-1 | K2: Cajas import | L2: Total | M2: Observaciones
A3: counter_name | B3: deposit_id | C3: rack_id | D3: Fecha | E3: Código | F3: Referencia | G3: Cajas | H3: Sueltos | I3: Cajas 0x0 | J3: Sueltos | L3: Unidades
A4: VICTORIA | B4: 2 | C4: 1 | D4: 27-01-26 | E4: 1611 | F4: {=IFERROR(_xlfn.XLOOKUP(TEXT(E4,"0000"),TEXT(Catalog!A:A,"0000"),Catalog!B:B),"")} -> OPB.KAST OLINTHOS 2RIJ 24 PE | G4: 22
A5: VICTORIA | B5: 2 | C5: 1 | D5: 27-01-26 | E5: 1612 | F5: {=IFERROR(_xlfn.XLOOKUP(TEXT(E5,"0000"),TEXT(Catalog!A:A,"0000"),Catalog!B:B),"")} -> OPB.KAST OLINTHOS 3RIJ 36 PE | G5: 2
A6: VICTORIA | B6: 2 | C6: 1 | D6: 27-01-26 | E6: 1506 | F6: {=IFERROR(_xlfn.XLOOKUP(TEXT(E6,"0000"),TEXT(Catalog!A:A,"0000"),Catalog!B:B),"")} -> OPBOUWKAST 2-RIJ 36PE 610285 | G6: 1 | M6: Producto sin codigo por antiguo, este codigo mas nuevo aprox.
A7: VICTORIA | B7: 2 | C7: 1 | D7: 27-01-26 | E7: 1511 | F7: {=IFERROR(_xlfn.XLOOKUP(TEXT(E7,"0000"),TEXT(Catalog!A:A,"0000"),Catalog!B:B),"")} -> INBOUWKAST 2-RIJ 28MOD 610373 | G7: 8
A8: VICTORIA | B8: 2 | C8: 1 | D8: 27-01-26 | E8: 7196 | F8: {=IFERROR(_xlfn.XLOOKUP(TEXT(E8,"0000"),TEXT(Catalog!A:A,"0000"),Catalog!B:B),"")} -> INB.KAST MP56 METALBOX NG | G8: 4
A9: VICTORIA | B9: 2 | C9: 1 | D9: 27-01-26 | E9: 7195 | F9: {=IFERROR(_xlfn.XLOOKUP(TEXT(E9,"0000"),TEXT(Catalog!A:A,"0000"),Catalog!B:B),"")} -> INB.KAST MP42 METALBOX NG | G9: 7
A10: VICTORIA | B10: 2 | C10: 1 | D10: 27-01-26 | E10: 7193 | F10: {=IFERROR(_xlfn.XLOOKUP(TEXT(E10,"0000"),TEXT(Catalog!A:A,"0000"),Catalog!B:B),"")} -> INB.KAST MP14 METALBOX NG | G10: 8
D13: A-2 | K13: Cajas import | L13: Total | M13: Observaciones
D14: Fecha | E14: Código | F14: Referencia | G14: Cajas | H14: Sueltos | I14: Cajas 0x0 | J14: Sueltos | L14: Unidades
A15: VICTORIA | B15: 2 | C15: 2 | D15: 27-01-26 | E15: 7144 | F15: {=IFERROR(_xlfn.XLOOKUP(TEXT(E15,"0000"),TEXT(Catalog!A:A,"0000"),Catalog!B:B),"")} -> OPB.KAST WD 6MD R1306BR1 | G15: 8
A16: VICTORIA | B16: 2 | C16: 2 | D16: 27-01-26 | E16: 7148 | F16: {=IFERROR(_xlfn.XLOOKUP(TEXT(E16,"0000"),TEXT(Catalog!A:A,"0000"),Catalog!B:B),"")} -> OPB.KAST WD 8MD 1308BR1 | G16: 6
A17: VICTORIA | B17: 2 | C17: 2 | D17: 27-01-26 | E17: 7168 | F17: {=IFERROR(_xlfn.XLOOKUP(TEXT(E17,"0000"),TEXT(Catalog!A:A,"0000"),Catalog!B:B),"")} -> OPB.KAST WD 36MD 1336PR1 | G17: 2
A18: VICTORIA | B18: 2 | C18: 2 | D18: 27-01-26 | E18: 7194 | F18: {=IFERROR(_xlfn.XLOOKUP(TEXT(E18,"0000"),TEXT(Catalog!A:A,"0000"),Catalog!B:B),"")} -> INB.KAST MP28 METALBOX NG | G18: 12
D21: A-3 | K21: Cajas import | L21: Total | M21: Observaciones
D22: Fecha | E22: Código | F22: Referencia | G22: Cajas | H22: Sueltos | I22: Cajas 0x0 | J22: Sueltos | L22: Unidades
A23: VICTORIA | B23: 2 | C23: 3 | D23: 27-01-26 | E23: 1507 | F23: {=IFERROR(_xlfn.XLOOKUP(TEXT(E23,"0000"),TEXT(Catalog!A:A,"0000"),Catalog!B:B),"")} -> OPBOUWKAST4-RIJ VA 424 T 48PE | G23: 2
A24: VICTORIA | B24: 2 | C24: 3 | D24: 27-01-26 | E24: 1665 | F24: {=IFERROR(_xlfn.XLOOKUP(TEXT(E24,"0000"),TEXT(Catalog!A:A,"0000"),Catalog!B:B),"")} -> MOELLER INB BF-U-5/120 | G24: 2
A25: VICTORIA | B25: 2 | C25: 3 | D25: 27-01-26 | E25: 7151 | F25: {=IFERROR(_xlfn.XLOOKUP(TEXT(E25,"0000"),TEXT(Catalog!A:A,"0000"),Catalog!B:B),"")} -> OPB.KAST 28MD 5281R1 | G25: 31
A26: VICTORIA | B26: 2 | C26: 3 | D26: 27-01-26 | E26: 1657 | F26: {=IFERROR(_xlfn.XLOOKUP(TEXT(E26,"0000"),TEXT(Catalog!A:A,"0000"),Catalog!B:B),"")} -> MOELLER OPB BF-0-5/120 | G26: 1
A27: VICTORIA | B27: 2 | C27: 3 | D27: 27-01-26 | F27: Cajas de sueltos | M27: Foto
D30: A-4 | K30: Cajas import | L30: Total | M30: Observaciones
D31: Fecha | E31: Código | F31: Referencia | G31: Cajas | H31: Sueltos | I31: Cajas 0x0 | J31: Sueltos | L31: Unidades
A32: VICTORIA | B32: 2 | C32: 4 | D32: 27-01-26 | E32: 1664 | F32: {=IFERROR(_xlfn.XLOOKUP(TEXT(E32,"0000"),TEXT(Catalog!A:A,"0000"),Catalog!B:B),"")} -> MOELLER INB BF-U-4/96 | G32: 7
A33: VICTORIA | B33: 2 | C33: 4 | D33: 27-01-26 | E33: 7147 | F33: {=IFERROR(_xlfn.XLOOKUP(TEXT(E33,"0000"),TEXT(Catalog!A:A,"0000"),Catalog!B:B),"")} -> OPB.KAST WD 48MD 1348R1 | G33: 6
A34: VICTORIA | B34: 2 | C34: 4 | D34: 27-01-26 | E34: 7184 | F34: {=IFERROR(_xlfn.XLOOKUP(TEXT(E34,"0000"),TEXT(Catalog!A:A,"0000"),Catalog!B:B),"")} -> INB.KAST MP14 METALBOX | G34: 2
A35: VICTORIA | B35: 2 | C35: 4 | D35: 27-01-26 | E35: 7193 | F35: {=IFERROR(_xlfn.XLOOKUP(TEXT(E35,"0000"),TEXT(Catalog!A:A,"0000"),Catalog!B:B),"")} -> INB.KAST MP14 METALBOX NG | G35: 22
D38: A-5 | K38: Cajas import | L38: Total | M38: Observaciones
D39: Fecha | E39: Código | F39: Referencia | G39: Cajas | H39: Sueltos | I39: Cajas 0x0 | J39: Sueltos | L39: Unidades
A40: VICTORIA | B40: 2 | C40: 5 | D40: 27-01-26 | E40: 1985 | F40: {=IFERROR(_xlfn.XLOOKUP(TEXT(E40,"0000"),TEXT(Catalog!A:A,"0000"),Catalog!B:B),"")} -> MESPATROON HOUDER 160 A-NH-00 | G40: 36
A41: VICTORIA | B41: 2 | C41: 5 | D41: 27-01-26 | E41: 1988 | F41: {=IFERROR(_xlfn.XLOOKUP(TEXT(E41,"0000"),TEXT(Catalog!A:A,"0000"),Catalog!B:B),"")} -> MESPATROON HOUDER 400 A-NH-2 | G41: 22
A42: VICTORIA | B42: 2 | C42: 5 | D42: 27-01-26 | E42: 1987 | F42: {=IFERROR(_xlfn.XLOOKUP(TEXT(E42,"0000"),TEXT(Catalog!A:A,"0000"),Catalog!B:B),"")} -> MESPATROON HOUDER 250 A-NH-1 | G42: 1
A43: VICTORIA | B43: 2 | C43: 5 | D43: 27-01-26 | E43: 1659 | F43: {=IFERROR(_xlfn.XLOOKUP(TEXT(E43,"0000"),TEXT(Catalog!A:A,"0000"),Catalog!B:B),"")} -> MOELLER OPB BF-0-3/72 | G43: 7
D46: A-6 | K46: Cajas import | L46: Total | M46: Observaciones
D47: Fecha | E47: Código | F47: Referencia | G47: Cajas | H47: Sueltos | I47: Cajas 0x0 | J47: Sueltos | L47: Unidades
A48: VICTORIA | B48: 2 | C48: 6 | D48: 27-01-26 | E48: 7191 | F48: {=IFERROR(_xlfn.XLOOKUP(TEXT(E48,"0000"),TEXT(Catalog!A:A,"0000"),Catalog!B:B),"")} -> EARTH TERMINAL GREEN | H48: 53
A49: VICTORIA | B49: 2 | C49: 6 | D49: 27-01-26 | E49: 1658 | F49: {=IFERROR(_xlfn.XLOOKUP(TEXT(E49,"0000"),TEXT(Catalog!A:A,"0000"),Catalog!B:B),"")} -> MOELLER OPB BF-0-6/144 | G49: 3
A50: VICTORIA | B50: 2 | C50: 6 | D50: 27-01-26 | E50: 1666 | F50: {=IFERROR(_xlfn.XLOOKUP(TEXT(E50,"0000"),TEXT(Catalog!A:A,"0000"),Catalog!B:B),"")} -> MOELLER INB BF-U-6/144 | G50: 5
...

Sheet D3 (V) Fixed
D1: Deposito Nro 3
D2: C2 | K2: Cajas import | L2: Total | M2: Observaciones
D3: Fecha | E3: Código | F3: Referencia | G3: Cajas | H3: Sueltos | I3: Cajas 0x0 | J3: Sueltos | L3: Unidades
A4: VICTORIA | B4: 3 | C4: 26 | D4: 30-01-2026 | E4: 15144 | F4: {=IFERROR(_xlfn.XLOOKUP(TEXT(E4,"0000"),TEXT(Catalog!A:A,"0000"),Catalog!B:B),"")} -> OPB.KAST WD 36MD CDN36PT/RR | G4: 21
A5: VICTORIA | B5: 3 | C5: 26 | D5: 30-01-2026 | E5: 15145 | F5: {=IFERROR(_xlfn.XLOOKUP(TEXT(E5,"0000"),TEXT(Catalog!A:A,"0000"),Catalog!B:B),"")} -> OPB.KAST WD 54MD CDP54 PT/RR | G5: 12
A6: VICTORIA | B6: 3 | C6: 26 | D6: 30-01-2026 | E6: 7052 | F6: {=IFERROR(_xlfn.XLOOKUP(TEXT(E6,"0000"),TEXT(Catalog!A:A,"0000"),Catalog!B:B),"")} -> JUNCTION BOX 125A 4*11 | G6: 2
A7: VICTORIA | B7: 3 | C7: 26 | D7: 30-01-2026 | E7: 7051 | F7: {=IFERROR(_xlfn.XLOOKUP(TEXT(E7,"0000"),TEXT(Catalog!A:A,"0000"),Catalog!B:B),"")} -> JUNCTION BOX 125A 4*7 | G7: 37
A8: VICTORIA | B8: 3
A9: VICTORIA | B9: 3 | D9: C1 | K9: Cajas import | L9: Total | M9: Observaciones
A10: VICTORIA | B10: 3 | D10: Fecha | E10: Código | F10: Referencia | G10: Cajas | H10: Sueltos | I10: Cajas 0x0 | J10: Sueltos | L10: Unidades
A11: VICTORIA | B11: 3 | C11: 21 | D11: 30-01-2026 | E11: 0615 | F11: {=IFERROR(_xlfn.XLOOKUP(TEXT(E11,"0000"),TEXT(Catalog!A:A,"0000"),Catalog!B:B),"")} -> ZEKERING 63A | G11: 1325
A12: VICTORIA | B12: 3 | C12: 21 | D12: 30-01-2026 | E12: 0614 | F12: {=IFERROR(_xlfn.XLOOKUP(TEXT(E12,"0000"),TEXT(Catalog!A:A,"0000"),Catalog!B:B),"")} -> ZEKERING 50A | G12: 950
A13: VICTORIA | B13: 3 | C13: 21 | D13: 30-01-2026 | E13: 0613 | F13: {=IFERROR(_xlfn.XLOOKUP(TEXT(E13,"0000"),TEXT(Catalog!A:A,"0000"),Catalog!B:B),"")} -> ZEKERING 35A | G13: 875
A14: VICTORIA | B14: 3 | C14: 21 | D14: 30-01-2026 | E14: 0612 | F14: {=IFERROR(_xlfn.XLOOKUP(TEXT(E14,"0000"),TEXT(Catalog!A:A,"0000"),Catalog!B:B),"")} -> ZEKERING 25A | G14: 477
A15: VICTORIA | B15: 3 | C15: 21 | D15: 30-01-2026 | E15: 0611 | F15: {=IFERROR(_xlfn.XLOOKUP(TEXT(E15,"0000"),TEXT(Catalog!A:A,"0000"),Catalog!B:B),"")} -> ZEKERING 20A | G15: 1300
A16: VICTORIA | B16: 3 | C16: 21 | D16: 30-01-2026 | E16: 0610 | F16: {=IFERROR(_xlfn.XLOOKUP(TEXT(E16,"0000"),TEXT(Catalog!A:A,"0000"),Catalog!B:B),"")} -> ZEKERING 16A | G16: 500
A17: VICTORIA | B17: 3
A18: VICTORIA | B18: 3 | D18: C7 | K18: Cajas import | L18: Total | M18: Observaciones
A19: VICTORIA | B19: 3 | D19: Fecha | E19: Código | F19: Referencia | G19: Cajas | H19: Sueltos | I19: Cajas 0x0 | J19: Sueltos | L19: Unidades
A20: VICTORIA | B20: 3 | C20: 31 | D20: 30-01-2026 | E20: 0577 | F20: {=IFERROR(_xlfn.XLOOKUP(TEXT(E20,"0000"),TEXT(Catalog!A:A,"0000"),Catalog!B:B),"")} -> LASDOPPEN 12-24 mm | G20: 220 | M20: 1650 STUCKS
A21: VICTORIA | B21: 3 | C21: 31 | D21: 30-01-2026 | E21: 0575 | F21: {=IFERROR(_xlfn.XLOOKUP(TEXT(E21,"0000"),TEXT(Catalog!A:A,"0000"),Catalog!B:B),"")} -> LASDOPPEN 3.0-12.5 mm | G21: 100 | M21: 5000 STUCKS
A22: VICTORIA | B22: 3 | C22: 31 | D22: 30-01-2026 | E22: 0576 | F22: {=IFERROR(_xlfn.XLOOKUP(TEXT(E22,"0000"),TEXT(Catalog!A:A,"0000"),Catalog!B:B),"")} -> LASDOPPEN 7.5-18.0 mm | G22: 80 | M22: 2400 STUCKS
A23: VICTORIA | B23: 3 | C23: 31 | D23: 30-01-2026 | E23: 7176 | F23: {=IFERROR(_xlfn.XLOOKUP(TEXT(E23,"0000"),TEXT(Catalog!A:A,"0000"),Catalog!B:B),"")} -> INSTEEK FLEXIBLE CLE54 | G23: 60
A24: VICTORIA | B24: 3 | C24: 31 | D24: 30-01-2026 | E24: 0569 | F24: {=IFERROR(_xlfn.XLOOKUP(TEXT(E24,"0000"),TEXT(Catalog!A:A,"0000"),Catalog!B:B),"")} -> CONEX STEEKKLEM 3-VOUDIG | G24: 160 | M24: 12000 STUCKS
A25: VICTORIA | B25: 3 | C25: 31 | D25: 30-01-2026 | E25: 0570 | F25: {=IFERROR(_xlfn.XLOOKUP(TEXT(E25,"0000"),TEXT(Catalog!A:A,"0000"),Catalog!B:B),"")} -> CONEX STEEKKLEM 4-VOUDIG | G25: 160 | M25: 12000 STUCKS
A26: VICTORIA | B26: 3 | C26: 31 | D26: 30-01-2026 | E26: 0571 | F26: {=IFERROR(_xlfn.XLOOKUP(TEXT(E26,"0000"),TEXT(Catalog!A:A,"0000"),Catalog!B:B),"")} -> CONEX STEEKKLEM 5-VOUDIG | G26: 140 | M26: 10500 STUCKS
A27: VICTORIA | B27: 3 | C27: 31 | D27: 30-01-2026 | E27: 15143 | F27: {=IFERROR(_xlfn.XLOOKUP(TEXT(E27,"0000"),TEXT(Catalog!A:A,"0000"),Catalog!B:B),"")} -> OPB.KAST WD 24MD CDN24PT/RR | G27: 1 | M27: CAJA ROTA HAY OTRAS C10
A28: VICTORIA | B28: 3
A29: VICTORIA | B29: 3 | D29: C3 | K29: Cajas import | L29: Total | M29: Observaciones
A30: VICTORIA | B30: 3 | D30: Fecha | E30: Código | F30: Referencia | G30: Cajas | H30: Sueltos | I30: Cajas 0x0 | J30: Sueltos | L30: Unidades
A31: VICTORIA | B31: 3 | C31: 27 | D31: 30-01-2026 | E31: 0631 | F31: {=IFERROR(_xlfn.XLOOKUP(TEXT(E31,"0000"),TEXT(Catalog!A:A,"0000"),Catalog!B:B),"")} -> KSV PATRONEN 160A NH 00 | G31: 5X3 | L31: 15
A32: VICTORIA | B32: 3 | C32: 27 | D32: 30-01-2026 | E32: 0630 | F32: {=IFERROR(_xlfn.XLOOKUP(TEXT(E32,"0000"),TEXT(Catalog!A:A,"0000"),Catalog!B:B),"")} -> KSV PATRONEN 125A NH 00 | G32: 17X3 | L32: 51 | M32: CONFIRMAR CODIGO
A33: VICTORIA | B33: 3 | C33: 27 | D33: 30-01-2026 | E33: 0628 | F33: {=IFERROR(_xlfn.XLOOKUP(TEXT(E33,"0000"),TEXT(Catalog!A:A,"0000"),Catalog!B:B),"")} -> KSV PATRONEN 80A NH 00 | G33: 9X9 | H33: 1 | L33: 81
A34: VICTORIA | B34: 3 | C34: 27 | D34: 30-01-2026 | E34: 0627 | F34: {=IFERROR(_xlfn.XLOOKUP(TEXT(E34,"0000"),TEXT(Catalog!A:A,"0000"),Catalog!B:B),"")} -> KSV PATRONEN 63A NH 00 | G34: 5X3 | L34: 15
A35: VICTORIA | B35: 3 | C35: 27 | D35: 30-01-2026 | E35: 0625 | F35: {=IFERROR(_xlfn.XLOOKUP(TEXT(E35,"0000"),TEXT(Catalog!A:A,"0000"),Catalog!B:B),"")} -> KSV PATRONEN 35A NH 00 | G35: 35X3 | L35: 105
A36: VICTORIA | B36: 3 | C36: 27 | D36: 30-01-2026 | E36: 0624 | F36: {=IFERROR(_xlfn.XLOOKUP(TEXT(E36,"0000"),TEXT(Catalog!A:A,"0000"),Catalog!B:B),"")} -> KSV PATRONEN 25A NH 00 | G36: 12X3 | L36: 36
A37: VICTORIA | B37: 3
A38: VICTORIA | B38: 3 | D38: C4 | K38: Cajas import | L38: Total | M38: Observaciones
A39: VICTORIA | B39: 3 | D39: Fecha | E39: Código | F39: Referencia | G39: Cajas | H39: Sueltos | I39: Cajas 0x0 | J39: Sueltos | L39: Unidades
A40: VICTORIA | B40: 3 | C40: 28 | D40: 30-01-2026 | E40: 1153 | F40: {=IFERROR(_xlfn.XLOOKUP(TEXT(E40,"0000"),TEXT(Catalog!A:A,"0000"),Catalog!B:B),"")} -> DEKSEL INB DOOS AM 4x4" 2-VOUD | G40: 15x50 | L40: 750
...

Sheet D1 (M) Fixed
D1: Deposito Nro 1
D2: A-1 | K2: Cajas import | L2: Total | M2: Observaciones
D3: Fecha | E3: Código | F3: Referencia | G3: Cajas | H3: Sueltos | I3: Cajas 0x0 | J3: Sueltos | L3: Unidades
A4: MALINA | B4: 1 | C4: 1 | D4: 26-01-26 | E4: 3229 | G4: 81
D7: A-2 | K7: Cajas import | L7: Total | M7: Observaciones
D8: Fecha | E8: Código | F8: Referencia | G8: Cajas | H8: Sueltos | I8: Cajas 0x0 | J8: Sueltos | L8: Unidades
A9: MALINA | B9: 1 | C9: 2 | D9: 26-01-26 | E9: 0103 | G9: 489
D12: A-3 | K12: Cajas import | L12: Total | M12: Observaciones
D13: Fecha | E13: Código | F13: Referencia | G13: Cajas | H13: Sueltos | I13: Cajas 0x0 | J13: Sueltos | L13: Unidades
A14: MALINA | B14: 1 | C14: 3 | D14: 26-01-26 | E14: 0101 | G14: 291
D17: A-4 | K17: Cajas import | L17: Total | M17: Observaciones
A18: MALINA | B18: 1 | C18: 4 | D18: Fecha | E18: Código | F18: Referencia | G18: Cajas | H18: Sueltos | I18: Cajas 0x0 | J18: Sueltos | L18: Unidades
D19: 26-01-26 | E19: 3231 | G19: 59
A22: 0 | D22: A-5 | K22: Cajas import | L22: Total | M22: Observaciones
D23: Fecha | E23: Código | F23: Referencia | G23: Cajas | H23: Sueltos | I23: Cajas 0x0 | J23: Sueltos | L23: Unidades
